Workbook

Sheet README
A1: MIRROR X · PRELIMINARY · MX-3777d2e495a9
A2: Статус | B2: PRELIMINARY — НЕ ГОТОВО К СДАЧЕ
A3: Snapshot | B3: MX-3777d2e495a9
A4: Срез | B4: 2026-10-29
A5: Правило цен | B5: Regular unadjusted close 2026-11-02; сейчас недоступно
A6: Единицы | B6: USD millions; shares millions; DCF result USD/share
A7: Факты | B7: Годовые факты из официальных документов; нужна сверка кварталов
A8: Допущения | B8: Все драйверы в DCF — аналитические предположения, не прогноз эмитента
A9: Расчёты | B9: Excel formulas + cached results; automatic recalc on open
A10: Источники | B10: SOURCES / COMPANY_FACTS
A11: Ограничение цен | B11: Общий набор UNDATED; не используется как текущая цена
A12: 12m target | B12: EV0*(1+WACC)-FCFF1-netDebt, затем / shares; долг/акции фиксированы
A13: PayPal | B13: BNPL требует нормализации; клиентские средства исключены из cash
A14: Риски | B14: Не является персональной рекомендацией. Buy не подтверждён.

Sheet UNIVERSE_SCREENING
A1: MIRROR X · PRELIMINARY · MX-3777d2e495a9
A2: Ticker | B2: Company | C2: Industry | D2: Price UNDATED | E2: Market cap USD | F2: P/E | G2: EBITDA USD | H2: Score | I2: Status | J2: Source
A3: MMM | B3: 3M | C3: Industrial Conglomerates | D3: 172.8 | E3: 89116835840 | F3: 25.6 | G3: 6497999872 | I3: UNDATED | J3: https://github.com/datasets/s-and-p-500-companies-financials/blob/main/data/constituents-financials.csv
A4: AOS | B4: A. O. Smith | C4: Building Products | D4: 60.86 | E4: 8271395840 | F4: 16.952646 | G4: 783699968 | H4: 81 | I4: UNDATED | J4: https://github.com/datasets/s-and-p-500-companies-financials/blob/main/data/constituents-financials.csv
A5: ABT | B5: Abbott Laboratories | C5: Health Care Equipment | D5: 102.64 | E5: 178779701248 | F5: 38.298508 | G5: 11953999872 | H5: 45 | I5: UNDATED | J5: https://github.com/datasets/s-and-p-500-companies-financials/blob/main/data/constituents-financials.csv
A6: ABBV | B6: AbbVie | C6: Biotechnology | D6: 285.99 | E6: 505377849344 | F6: 80.78813 | G6: 30762999808 | H6: 22 | I6: UNDATED | J6: https://github.com/datasets/s-and-p-500-companies-financials/blob/main/data/constituents-financials.csv
A7: ACN | B7: Accenture | C7: IT Consulting & Other Services | D7: 243.4 | E7: 148946698240 | F7: 17.336182 | G7: 13419352064 | H7: 54 | I7: UNDATED | J7: https://github.com/datasets/s-and-p-500-companies-financials/blob/main/data/constituents-financials.csv
A8: ADBE | B8: Adobe Inc. | C8: Application Software | D8: 249.76 | E8: 97206591488 | F8: 13.86785 | G8: 9916999680 | H8: 95 | I8: UNDATED | J8: https://github.com/datasets/s-and-p-500-companies-financials/blob/main/data/constituents-financials.csv
A9: AMD | B9: Advanced Micro Devices | C9: Semiconductors | D9: 578.44 | E9: 944288825344 | F9: 147.56122 | G9: 9562000384 | H9: 4 | I9: UNDATED | J9: https://github.com/datasets/s-and-p-500-companies-financials/blob/main/data/constituents-financials.csv
A10: AES | B10: AES Corporation | C10: Independent Power Producers & Energy Traders | D10: 14.98 | E10: 10683102208 | F10: 5.6315784 | G10: 4070000128 | I10: UNDATED | J10: https://github.com/datasets/s-and-p-500-companies-financials/blob/main/data/constituents-financials.csv
A11: AFL | B11: Aflac | C11: Life & Health Insurance | D11: 121.75 | E11: 61038546944 | F11: 13.119613 | G11: 6064999936 | I11: UNDATED | J11: https://github.com/datasets/s-and-p-500-companies-financials/blob/main/data/constituents-financials.csv
A12: A | B12: Agilent Technologies | C12: Life Sciences Tools & Services | D12: 181.48 | E12: 51164450816 | F12: 35.034748 | G12: 2080000000 | H12: 67 | I12: UNDATED | J12: https://github.com/datasets/s-and-p-500-companies-financials/blob/main/data/constituents-financials.csv
A13: APD | B13: Air Products | C13: Industrial Gases | D13: 307.2 | E13: 68408999936 | G13: 4652199936 | I13: UNDATED | J13: https://github.com/datasets/s-and-p-500-companies-financials/blob/main/data/constituents-financials.csv
A14: ABNB | B14: Airbnb | C14: Hotels, Resorts & Cruise Lines | D14: 166.045 | E14: 99425361920 | F14: 38.43634 | G14: 2760999936 | H14: 21 | I14: UNDATED | J14: https://github.com/datasets/s-and-p-500-companies-financials/blob/main/data/constituents-financials.csv
A15: AKAM | B15: Akamai Technologies | C15: Internet Services & Infrastructure | D15: 98.1 | E15: 14098598912 | F15: 36.066177 | G15: 1079897984 | I15: UNDATED | J15: https://github.com/datasets/s-and-p-500-companies-financials/blob/main/data/constituents-financials.csv
A16: ALB | B16: Albemarle Corporation | C16: Specialty Chemicals | D16: 96.96 | E16: 11441770496 | F16: 372.9231 | G16: 1482468992 | H16: 36 | I16: UNDATED | J16: https://github.com/datasets/s-and-p-500-companies-financials/blob/main/data/constituents-financials.csv
A17: ARE | B17: Alexandria Real Estate Equities | C17: Office REITs | D17: 39.91 | E17: 6950751232 | G17: 1698887936 | I17: UNDATED | J17: https://github.com/datasets/s-and-p-500-companies-financials/blob/main/data/constituents-financials.csv
A18: ALGN | B18: Align Technology | C18: Health Care Supplies | D18: 153.62 | E18: 10913142784 | F18: 26.440619 | G18: 925662016 | I18: UNDATED | J18: https://github.com/datasets/s-and-p-500-companies-financials/blob/main/data/constituents-financials.csv
A19: ALLE | B19: Allegion | C19: Building Products | D19: 180.66 | E19: 15362745344 | F19: 22.47015 | G19: 1099000064 | H19: 59 | I19: UNDATED | J19: https://github.com/datasets/s-and-p-500-companies-financials/blob/main/data/constituents-financials.csv
A20: LNT | B20: Alliant Energy | C20: Electric Utilities | D20: 69.37 | E20: 17986580480 | F20: 21.543478 | G20: 1828999936 | H20: 38 | I20: UNDATED | J20: https://github.com/datasets/s-and-p-500-companies-financials/blob/main/data/constituents-financials.csv
A21: ALL | B21: Allstate | C21: Property & Casualty Insurance | D21: 250.2 | E21: 63265058816 | F21: 5.0060024 | G21: 17116000256 | I21: UNDATED | J21: https://github.com/datasets/s-and-p-500-companies-financials/blob/main/data/constituents-financials.csv
A22: GOOGL | B22: Alphabet Inc. (Class A) | C22: Interactive Media & Services | D22: 324.89 | E22: 3973383716864 | F22: 16.083664 | G22: 173164003328 | I22: UNDATED | J22: https://github.com/datasets/s-and-p-500-companies-financials/blob/main/data/constituents-financials.csv
A23: GOOG | B23: Alphabet Inc. (Class C) | C23: Interactive Media & Services | D23: 321.89 | E23: 3936694042624 | F23: 15.895803 | G23: 173164003328 | I23: UNDATED | J23: https://github.com/datasets/s-and-p-500-companies-financials/blob/main/data/constituents-financials.csv
A24: MO | B24: Altria | C24: Tobacco | D24: 72.99 | E24: 121874604032 | F24: 15.463984 | G24: 12769999872 | I24: UNDATED | J24: https://github.com/datasets/s-and-p-500-companies-financials/blob/main/data/constituents-financials.csv
A25: AMZN | B25: Amazon | C25: Broadline Retail | D25: 254.6 | E25: 2746195378176 | F25: 20.482702 | G25: 168911994880 | I25: UNDATED | J25: https://github.com/datasets/s-and-p-500-companies-financials/blob/main/data/constituents-financials.csv
A26: AMCR | B26: Amcor | C26: Paper & Plastic Packaging Products & Materials | D26: 45.66 | E26: 21092440064 | F26: 19.184874 | G26: 3536000000 | I26: UNDATED | J26: https://github.com/datasets/s-and-p-500-companies-financials/blob/main/data/constituents-financials.csv
A27: AMTM | B27: Amentum | C27: Diversified Support Services | D27: 21.69 | E27: 5303344128 | F27: 26.132532 | G27: 1006000000 | I27: UNDATED | J27: https://github.com/datasets/s-and-p-500-companies-financials/blob/main/data/constituents-financials.csv
A28: AEE | B28: Ameren | C28: Multi-Utilities | D28: 108 | E28: 29899071488 | F28: 19.148937 | G28: 3910000128 | H28: 57 | I28: UNDATED | J28: https://github.com/datasets/s-and-p-500-companies-financials/blob/main/data/constituents-financials.csv
A29: AEP | B29: American Electric Power | C29: Electric Utilities | D29: 128.2 | E29: 69791744000 | F29: 22.21837 | G29: 9029000192 | H29: 33 | I29: UNDATED | J29: https://github.com/datasets/s-and-p-500-companies-financials/blob/main/data/constituents-financials.csv
A30: AXP | B30: American Express | C30: Consumer Finance | D30: 317.94 | E30: 213195309056 | F30: 17.624168 | I30: UNDATED | J30: https://github.com/datasets/s-and-p-500-companies-financials/blob/main/data/constituents-financials.csv
A31: AIG | B31: American International Group | C31: Multi-line Insurance | D31: 79.88 | E31: 41768706048 | F31: 14.576642 | G31: 8145999872 | I31: UNDATED | J31: https://github.com/datasets/s-and-p-500-companies-financials/blob/main/data/constituents-financials.csv
A32: AMT | B32: American Tower | C32: Telecom Tower REITs | D32: 183.75 | E32: 85620162560 | F32: 25.880281 | G32: 7025900032 | I32: UNDATED | J32: https://github.com/datasets/s-and-p-500-companies-financials/blob/main/data/constituents-financials.csv
A33: AWK | B33: American Water Works | C33: Water Utilities | D33: 139.79 | E33: 27780325376 | F33: 24.43881 | G33: 2912999936 | I33: UNDATED | J33: https://github.com/datasets/s-and-p-500-companies-financials/blob/main/data/constituents-financials.csv
A34: AMP | B34: Ameriprise Financial | C34: Asset Management & Custody Banks | D34: 489.8 | E34: 43298320384 | F34: 11.825206 | I34: UNDATED | J34: https://github.com/datasets/s-and-p-500-companies-financials/blob/main/data/constituents-financials.csv
A35: AME | B35: Ametek | C35: Electrical Components & Equipment | D35: 248.13 | E35: 56872144896 | F35: 36.276318 | G35: 2500681984 | H35: 74 | I35: UNDATED | J35: https://github.com/datasets/s-and-p-500-companies-financials/blob/main/data/constituents-financials.csv
A36: AMGN | B36: Amgen | C36: Biotechnology | D36: 451.83 | E36: 244273741824 | F36: 27.822044 | G36: 17268000768 | H36: 58 | I36: UNDATED | J36: https://github.com/datasets/s-and-p-500-companies-financials/blob/main/data/constituents-financials.csv
A37: APH | B37: Amphenol | C37: Electronic Components | D37: 80.96 | E37: 199644676096 | F37: 39.11111 | G37: 9463700480 | I37: UNDATED | J37: https://github.com/datasets/s-and-p-500-companies-financials/blob/main/data/constituents-financials.csv
A38: ADI | B38: Analog Devices | C38: Semiconductors | D38: 428.27 | E38: 207524855808 | F38: 50.50354 | G38: 6922700800 | H38: 29 | I38: UNDATED | J38: https://github.com/datasets/s-and-p-500-companies-financials/blob/main/data/constituents-financials.csv
A39: ANSS | B39: Ansys | C39: Application Software | I39: UNDATED | J39: https://github.com/datasets/s-and-p-500-companies-financials/blob/main/data/constituents-financials.csv
A40: AON | B40: Aon | C40: Insurance Brokers | D40: 315.72 | E40: 66972246016 | F40: 17.40463 | G40: 5900000256 | I40: UNDATED | J40: https://github.com/datasets/s-and-p-500-companies-financials/blob/main/data/constituents-financials.csv
...

Sheet SOURCES
A1: MIRROR X · PRELIMINARY · MX-3777d2e495a9
A2: Ticker | B2: Source | C2: Period | D2: Published / signed | E2: Status
A3: UNIVERSE | B3: https://github.com/datasets/s-and-p-500-companies-financials/blob/main/data/constituents-financials.csv | C3: UNKNOWN | D3: UNKNOWN | E3: UNDATED
A4: ADBE | B4: https://www.adobe.com/cc-shared/assets/investor-relations/pdfs/adbe-2025-annual-report.pdf | C4: 2025-11-28 | D4: 2026-01-15 | E4: ANNUAL FACTS / NEEDS QUARTERLY UPDATE
A5: PYPL | B5: https://www.sec.gov/Archives/edgar/data/1633917/000163391726000024/pypl-20251231.htm | C5: 2025-12-31 | D5: 2026-02-03 | E5: ANNUAL FACTS / NEEDS QUARTERLY UPDATE
A6: NKE | B6: https://investors.nike.com/sec-filings/all-sec-filings/content/0000320187-26-000088/nke-20260531.htm | C6: 2026-05-31 | D6: 2026-07-15 | E6: ANNUAL FACTS / NEEDS QUARTERLY UPDATE
A7: MACRO | B7: https://www.federalreserve.gov/newsevents/pressreleases/monetary20261028a.htm | C7: 2026-10-28 | D7: 2026-10-28 | E7: Fed funds held 3.75–4.00%; not risk-free yield

Sheet COMPANY_FACTS
A1: MIRROR X · PRELIMINARY · MX-3777d2e495a9
A2: Ticker | B2: Period end | C2: Revenue | D2: Operating income | E2: Cash + ST inv. | F2: Debt | G2: Diluted shares | H2: Effective tax | I2: Source
A3: ADBE | B3: 2025-11-28 | C3: 23769 | D3: 8706 | E3: 6595 | F3: 6210 | G3: 427 | H3: 0.1836501 | I3: https://www.adobe.com/cc-shared/assets/investor-relations/pdfs/adbe-2025-annual-report.pdf
A4: PYPL | B4: 2025-12-31 | C4: 33172 | D4: 6065 | E4: 10422 | F4: 9987 | G4: 968 | H4: 0.16830896 | I4: https://www.sec.gov/Archives/edgar/data/1633917/000163391726000024/pypl-20251231.htm
A5: NKE | B5: 2026-05-31 | C5: 46398 | D5: 3797 | E5: 9027 | F5: 7942 | G5: 1481 | H5: 0.20307692 | I5: https://investors.nike.com/sec-filings/all-sec-filings/content/0000320187-26-000088/nke-20260531.htm

Sheet DCF_ADBE
A1: MIRROR X · PRELIMINARY · MX-3777d2e495a9
A2: Драйвер / единицы | B2: Значение | C2: Классификация
A3: Revenue (USD mn) | B3: 23769 | C3: Annual report
A4: Annual growth | B4: 0.07 | C4: Analyst assumption
A5: Operating margin | B5: 0.35 | C5: Analyst assumption
A6: Tax rate | B6: 0.2 | C6: Analyst assumption
A7: D&A / revenue | B7: 0.02 | C7: Analyst assumption
A8: CapEx / revenue | B8: 0.02 | C8: Analyst assumption
A9: NWC / revenue | B9: 0.03 | C9: Analyst assumption
A10: WACC | B10: 0.1 | C10: Scenario; not a measured CAPM WACC
A11: Terminal growth | B11: 0.025 | C11: Analyst assumption
A12: Diluted shares (mn) | B12: 427 | C12: Annual weighted average
A13: Net debt (USD mn) | B13: -385 | C13: Debt - cash - short-term investments
A16: Forecast / USD mn | B16: 1 | C16: 2 | D16: 3 | E16: 4 | F16: 5
A17: Revenue | B17: =$B$3*(1+$B$4) -> 25432.83 | C17: =B17*(1+$B$4) -> 27213.128 | D17: =C17*(1+$B$4) -> 29118.047 | E17: =D17*(1+$B$4) -> 31156.31 | F17: =E17*(1+$B$4) -> 33337.252
A18: EBIT | B18: =B17*$B$5 -> 8901.4905 | C18: =C17*$B$5 -> 9524.5948 | D18: =D17*$B$5 -> 10191.316 | E18: =E17*$B$5 -> 10904.709 | F18: =F17*$B$5 -> 11668.038
A19: NOPAT | B19: =B18*(1-$B$6) -> 7121.1924 | C19: =C18*(1-$B$6) -> 7619.6759 | D19: =D18*(1-$B$6) -> 8153.0532 | E19: =E18*(1-$B$6) -> 8723.7669 | F19: =F18*(1-$B$6) -> 9334.4306
A20: D&A | B20: =B17*$B$7 -> 508.6566 | C20: =C17*$B$7 -> 544.26256 | D20: =D17*$B$7 -> 582.36094 | E20: =E17*$B$7 -> 623.12621 | F20: =F17*$B$7 -> 666.74504
A21: CapEx | B21: =B17*$B$8 -> 508.6566 | C21: =C17*$B$8 -> 544.26256 | D21: =D17*$B$8 -> 582.36094 | E21: =E17*$B$8 -> 623.12621 | F21: =F17*$B$8 -> 666.74504
A22: Delta NWC | B22: =(B17-$B$3)*$B$9 -> 49.9149 | C22: =(C17-B17)*$B$9 -> 53.408943 | D22: =(D17-C17)*$B$9 -> 57.147569 | E22: =(E17-D17)*$B$9 -> 61.147899 | F22: =(F17-E17)*$B$9 -> 65.428252
A23: FCFF | B23: =B19+B20-B21-B22 -> 7071.2775 | C23: =C19+C20-C21-C22 -> 7566.2669 | D23: =D19+D20-D21-D22 -> 8095.9056 | E23: =E19+E20-E21-E22 -> 8662.619 | F23: =F19+F20-F21-F22 -> 9269.0023
A24: PV FCFF | B24: =B23/(1+$B$10)^1 -> 6428.4341 | C24: =C23/(1+$B$10)^2 -> 6253.1132 | D24: =D23/(1+$B$10)^3 -> 6082.5737 | E24: =E23/(1+$B$10)^4 -> 5916.6853 | F24: =F23/(1+$B$10)^5 -> 5755.3212
A27: FCFF year 6 | B27: =F17*(1+$B$11)*($B$5*(1-$B$6)+$B$7-$B$8)-F17*$B$11*$B$9 -> 9542.7884
A28: Terminal value | B28: =B27/($B$10-$B$11) -> 127237.18
A29: PV terminal | B29: =B28/(1+$B$10)^5 -> 79004.277
A30: Enterprise value | B30: =SUM(B24:F24)+B29 -> 109440.4
A31: Equity value | B31: =B30-$B$13 -> 109825.4
A32: Fair value / share | B32: =B31/$B$12 -> 257.20235
A33: 12m model target / share | B33: =(B30*(1+$B$10)-B23-$B$13)/$B$12 -> 266.27206
A34: Terminal share / EV | B34: =B29/B30 -> 0.72189314
A36: Source | B36: https://www.adobe.com/cc-shared/assets/investor-relations/pdfs/adbe-2025-annual-report.pdf
A37: Model anchor FY | B37: 2025-11-28
A38: Do not treat as 02 Nov target | B38: PRELIMINARY
A39: Model check | B39: =IF(AND(B10>B11,B12>0,B27>0),"PASS","FAIL") -> PASS

Sheet DCF_PYPL
A1: MIRROR X · PRELIMINARY · MX-3777d2e495a9
A2: Драйвер / единицы | B2: Значение | C2: Классификация
A3: Revenue (USD mn) | B3: 33172 | C3: Annual report
A4: Annual growth | B4: 0.04 | C4: Analyst assumption
A5: Operating margin | B5: 0.18 | C5: Analyst assumption
A6: Tax rate | B6: 0.21 | C6: Analyst assumption
A7: D&A / revenue | B7: 0.03 | C7: Analyst assumption
A8: CapEx / revenue | B8: 0.025 | C8: Analyst assumption
A9: NWC / revenue | B9: 0.02 | C9: Analyst assumption
A10: WACC | B10: 0.105 | C10: Scenario; not a measured CAPM WACC
A11: Terminal growth | B11: 0.02 | C11: Analyst assumption
A12: Diluted shares (mn) | B12: 968 | C12: Annual weighted average
A13: Net debt (USD mn) | B13: -435 | C13: Debt - cash - short-term investments
A16: Forecast / USD mn | B16: 1 | C16: 2 | D16: 3 | E16: 4 | F16: 5
A17: Revenue | B17: =$B$3*(1+$B$4) -> 34498.88 | C17: =B17*(1+$B$4) -> 35878.835 | D17: =C17*(1+$B$4) -> 37313.989 | E17: =D17*(1+$B$4) -> 38806.548 | F17: =E17*(1+$B$4) -> 40358.81
A18: EBIT | B18: =B17*$B$5 -> 6209.7984 | C18: =C17*$B$5 -> 6458.1903 | D18: =D17*$B$5 -> 6716.5179 | E18: =E17*$B$5 -> 6985.1787 | F18: =F17*$B$5 -> 7264.5858
A19: NOPAT | B19: =B18*(1-$B$6) -> 4905.7407 | C19: =C18*(1-$B$6) -> 5101.9704 | D19: =D18*(1-$B$6) -> 5306.0492 | E19: =E18*(1-$B$6) -> 5518.2911 | F19: =F18*(1-$B$6) -> 5739.0228
A20: D&A | B20: =B17*$B$7 -> 1034.9664 | C20: =C17*$B$7 -> 1076.3651 | D20: =D17*$B$7 -> 1119.4197 | E20: =E17*$B$7 -> 1164.1964 | F20: =F17*$B$7 -> 1210.7643
A21: CapEx | B21: =B17*$B$8 -> 862.472 | C21: =C17*$B$8 -> 896.97088 | D21: =D17*$B$8 -> 932.84972 | E21: =E17*$B$8 -> 970.1637 | F21: =F17*$B$8 -> 1008.9703
A22: Delta NWC | B22: =(B17-$B$3)*$B$9 -> 26.5376 | C22: =(C17-B17)*$B$9 -> 27.599104 | D22: =(D17-C17)*$B$9 -> 28.703068 | E22: =(E17-D17)*$B$9 -> 29.851191 | F22: =(F17-E17)*$B$9 -> 31.045239
A23: FCFF | B23: =B19+B20-B21-B22 -> 5051.6975 | C23: =C19+C20-C21-C22 -> 5253.7654 | D23: =D19+D20-D21-D22 -> 5463.9161 | E23: =E19+E20-E21-E22 -> 5682.4727 | F23: =F19+F20-F21-F22 -> 5909.7716
A24: PV FCFF | B24: =B23/(1+$B$10)^1 -> 4571.672 | C24: =C23/(1+$B$10)^2 -> 4302.7501 | D24: =D23/(1+$B$10)^3 -> 4049.6472 | E24: =E23/(1+$B$10)^4 -> 3811.4326 | F24: =F23/(1+$B$10)^5 -> 3587.2307
A27: FCFF year 6 | B27: =F17*(1+$B$11)*($B$5*(1-$B$6)+$B$7-$B$8)-F17*$B$11*$B$9 -> 6043.4897
A28: Terminal value | B28: =B27/($B$10-$B$11) -> 71099.878
A29: PV terminal | B29: =B28/(1+$B$10)^5 -> 43157.618
A30: Enterprise value | B30: =SUM(B24:F24)+B29 -> 63480.351
A31: Equity value | B31: =B30-$B$13 -> 63915.351
A32: Fair value / share | B32: =B31/$B$12 -> 66.028255
A33: 12m model target / share | B33: =(B30*(1+$B$10)-B23-$B$13)/$B$12 -> 67.695341
A34: Terminal share / EV | B34: =B29/B30 -> 0.6798579
A36: Source | B36: https://www.sec.gov/Archives/edgar/data/1633917/000163391726000024/pypl-20251231.htm
A37: Model anchor FY | B37: 2025-12-31
A38: Do not treat as 02 Nov target | B38: PRELIMINARY
A39: Model check | B39: =IF(AND(B10>B11,B12>0,B27>0),"PASS","FAIL") -> PASS

Sheet DCF_NKE
A1: MIRROR X · PRELIMINARY · MX-3777d2e495a9
A2: Драйвер / единицы | B2: Значение | C2: Классификация
A3: Revenue (USD mn) | B3: 46398 | C3: Annual report
A4: Annual growth | B4: 0.035 | C4: Analyst assumption
A5: Operating margin | B5: 0.1 | C5: Analyst assumption
A6: Tax rate | B6: 0.22 | C6: Analyst assumption
A7: D&A / revenue | B7: 0.017 | C7: Analyst assumption
A8: CapEx / revenue | B8: 0.025 | C8: Analyst assumption
A9: NWC / revenue | B9: 0.1 | C9: Analyst assumption
A10: WACC | B10: 0.1 | C10: Scenario; not a measured CAPM WACC
A11: Terminal growth | B11: 0.02 | C11: Analyst assumption
A12: Diluted shares (mn) | B12: 1481 | C12: Annual weighted average
A13: Net debt (USD mn) | B13: -1085 | C13: Debt - cash - short-term investments
A16: Forecast / USD mn | B16: 1 | C16: 2 | D16: 3 | E16: 4 | F16: 5
A17: Revenue | B17: =$B$3*(1+$B$4) -> 48021.93 | C17: =B17*(1+$B$4) -> 49702.698 | D17: =C17*(1+$B$4) -> 51442.292 | E17: =D17*(1+$B$4) -> 53242.772 | F17: =E17*(1+$B$4) -> 55106.269
A18: EBIT | B18: =B17*$B$5 -> 4802.193 | C18: =C17*$B$5 -> 4970.2698 | D18: =D17*$B$5 -> 5144.2292 | E18: =E17*$B$5 -> 5324.2772 | F18: =F17*$B$5 -> 5510.6269
A19: NOPAT | B19: =B18*(1-$B$6) -> 3745.7105 | C19: =C18*(1-$B$6) -> 3876.8104 | D19: =D18*(1-$B$6) -> 4012.4988 | E19: =E18*(1-$B$6) -> 4152.9362 | F19: =F18*(1-$B$6) -> 4298.289
A20: D&A | B20: =B17*$B$7 -> 816.37281 | C20: =C17*$B$7 -> 844.94586 | D20: =D17*$B$7 -> 874.51896 | E20: =E17*$B$7 -> 905.12713 | F20: =F17*$B$7 -> 936.80658
A21: CapEx | B21: =B17*$B$8 -> 1200.5482 | C21: =C17*$B$8 -> 1242.5674 | D21: =D17*$B$8 -> 1286.0573 | E21: =E17*$B$8 -> 1331.0693 | F21: =F17*$B$8 -> 1377.6567
A22: Delta NWC | B22: =(B17-$B$3)*$B$9 -> 162.393 | C22: =(C17-B17)*$B$9 -> 168.07675 | D22: =(D17-C17)*$B$9 -> 173.95944 | E22: =(E17-D17)*$B$9 -> 180.04802 | F22: =(F17-E17)*$B$9 -> 186.3497
A23: FCFF | B23: =B19+B20-B21-B22 -> 3199.1421 | C23: =C19+C20-C21-C22 -> 3311.1121 | D23: =D19+D20-D21-D22 -> 3427.001 | E23: =E19+E20-E21-E22 -> 3546.946 | F23: =F19+F20-F21-F22 -> 3671.0891
A24: PV FCFF | B24: =B23/(1+$B$10)^1 -> 2908.311 | C24: =C23/(1+$B$10)^2 -> 2736.4563 | D24: =D23/(1+$B$10)^3 -> 2574.7566 | E24: =E23/(1+$B$10)^4 -> 2422.6119 | F24: =F23/(1+$B$10)^5 -> 2279.4575
A27: FCFF year 6 | B27: =F17*(1+$B$11)*($B$5*(1-$B$6)+$B$7-$B$8)-F17*$B$11*$B$9 -> 3824.3751
A28: Terminal value | B28: =B27/($B$10-$B$11) -> 47804.689
A29: PV terminal | B29: =B28/(1+$B$10)^5 -> 29682.95
A30: Enterprise value | B30: =SUM(B24:F24)+B29 -> 42604.544
A31: Equity value | B31: =B30-$B$13 -> 43689.544
A32: Fair value / share | B32: =B31/$B$12 -> 29.500029
A33: 12m model target / share | B33: =(B30*(1+$B$10)-B23-$B$13)/$B$12 -> 30.216648
A34: Terminal share / EV | B34: =B29/B30 -> 0.69670856
A36: Source | B36: https://investors.nike.com/sec-filings/all-sec-filings/content/0000320187-26-000088/nke-20260531.htm
A37: Model anchor FY | B37: 2026-05-31
A38: Do not treat as 02 Nov target | B38: PRELIMINARY
A39: Model check | B39: =IF(AND(B10>B11,B12>0,B27>0),"PASS","FAIL") -> PASS

Sheet SENSITIVITY
A1: MIRROR X · PRELIMINARY · MX-3777d2e495a9
A2: Ticker | B2: WACC / g | C2: -0.01 | D2: -0.005 | E2: 0 | F2: 0.005 | G2: 0.01
A3: ADBE | B3: 0.09 | C3: =((('DCF_ADBE'!$B$3*(1+'DCF_ADBE'!$B$4)^1*('DCF_ADBE'!$B$5*(1-'DCF_ADBE'!$B$6)+'DCF_ADBE'!$B$7-'DCF_ADBE'!$B$8)-'DCF_ADBE'!$B$3*(1+'DCF_ADBE'!$B$4)^0*'DCF_ADBE'!$B$4*'DCF_ADBE'!$B$9)/(1+0.09000000000000001)^1+('DCF_ADBE'!$B$3*(1+'DCF_ADBE'!$B$4)^2*('DCF_ADBE'!$B$5*(1-'DCF_ADBE'!$B$6)+'DCF_ADBE'!$B$7-'DCF_ADBE'!$B$8)-'DCF_ADBE'!$B$3*(1+'DCF_ADBE'!$B$4)^1*'DCF_ADBE'!$B$4*'DCF_ADBE'!$B$9)/(1+0.09000000000000001)^2+('DCF_ADBE'!$B$3*(1+'DCF_ADBE'!$B$4)^3*('DCF_ADBE'!$B$5*(1-'DCF_ADBE'!$B$6)+'DCF_ADBE'!$B$7-'DCF_ADBE'!$B$8)-'DCF_ADBE'!$B$3*(1+'DCF_ADBE'!$B$4)^2*'DCF_ADBE'!$B$4*'DCF_ADBE'!$B$9)/(1+0.09000000000000001)^3+('DCF_ADBE'!$B$3*(1+'DCF_ADBE'!$B$4)^4*('DCF_ADBE'!$B$5*(1-'DCF_ADBE'!$B$6)+'DCF_ADBE'!$B$7-'DCF_ADBE'!$B$8)-'DCF_ADBE'!$B$3*(1+'DCF_ADBE'!$B$4)^3*'DCF_ADBE'!$B$4*'DCF_ADBE'!$B$9)/(1+0.09000000000000001)^4+('DCF_ADBE'!$B$3*(1+'DCF_ADBE'!$B$4)^5*('DCF_ADBE'!$B$5*(1-'DCF_ADBE'!$B$6)+'DCF_ADBE'!$B$7-'DCF_ADBE'!$B$8)-'DCF_ADBE'!$B$3*(1+'DCF_ADBE'!$B$4)^4*'DCF_ADBE'!$B$4*'DCF_ADBE'!$B$9)/(1+0.09000000000000001)^5+('DCF_ADBE'!$B$3*(1+'DCF_ADBE'!$B$4)^5*(1+0.015000000000000001)*('DCF_ADBE'!$B$5*(1-'DCF_ADBE'!$B$6)+'DCF_ADBE'!$B$7-'DCF_ADBE'!$B$8)-'DCF_ADBE'!$B$3*(1+'DCF_ADBE'!$B$4)^5*0.015000000000000001*'DCF_ADBE'!$B$9)/(0.09000000000000001-0.015000000000000001)/(1+0.09000000000000001)^5-'DCF_ADBE'!$B$13)/'DCF_ADBE'!$B$12) -> 266.10433 | D3: =((('DCF_ADBE'!$B$3*(1+'DCF_ADBE'!$B$4)^1*('DCF_ADBE'!$B$5*(1-'DCF_ADBE'!$B$6)+'DCF_ADBE'!$B$7-'DCF_ADBE'!$B$8)-'DCF_ADBE'!$B$3*(1+'DCF_ADBE'!$B$4)^0*'DCF_ADBE'!$B$4*'DCF_ADBE'!$B$9)/(1+0.09000000000000001)^1+('DCF_ADBE'!$B$3*(1+'DCF_ADBE'!$B$4)^2*('DCF_ADBE'!$B$5*(1-'DCF_ADBE'!$B$6)+'DCF_ADBE'!$B$7-'DCF_ADBE'!$B$8)-'DCF_ADBE'!$B$3*(1+'DCF_ADBE'!$B$4)^1*'DCF_ADBE'!$B$4*'DCF_ADBE'!$B$9)/(1+0.09000000000000001)^2+('DCF_ADBE'!$B$3*(1+'DCF_ADBE'!$B$4)^3*('DCF_ADBE'!$B$5*(1-'DCF_ADBE'!$B$6)+'DCF_ADBE'!$B$7-'DCF_ADBE'!$B$8)-'DCF_ADBE'!$B$3*(1+'DCF_ADBE'!$B$4)^2*'DCF_ADBE'!$B$4*'DCF_ADBE'!$B$9)/(1+0.09000000000000001)^3+('DCF_ADBE'!$B$3*(1+'DCF_ADBE'!$B$4)^4*('DCF_ADBE'!$B$5*(1-'DCF_ADBE'!$B$6)+'DCF_ADBE'!$B$7-'DCF_ADBE'!$B$8)-'DCF_ADBE'!$B$3*(1+'DCF_ADBE'!$B$4)^3*'DCF_ADBE'!$B$4*'DCF_ADBE'!$B$9)/(1+0.09000000000000001)^4+('DCF_ADBE'!$B$3*(1+'DCF_ADBE'!$B$4)^5*('DCF_ADBE'!$B$5*(1-'DCF_ADBE'!$B$6)+'DCF_ADBE'!$B$7-'DCF_ADBE'!$B$8)-'DCF_ADBE'!$B$3*(1+'DCF_ADBE'!$B$4)^4*'DCF_ADBE'!$B$4*'DCF_ADBE'!$B$9)/(1+0.09000000000000001)^5+('DCF_ADBE'!$B$3*(1+'DCF_ADBE'!$B$4)^5*(1+0.02)*('DCF_ADBE'!$B$5*(1-'DCF_ADBE'!$B$6)+'DCF_ADBE'!$B$7-'DCF_ADBE'!$B$8)-'DCF_ADBE'!$B$3*(1+'DCF_ADBE'!$B$4)^5*0.02*'DCF_ADBE'!$B$9)/(0.09000000000000001-0.02)/(1+0.09000000000000001)^5-'DCF_ADBE'!$B$13)/'DCF_ADBE'!$B$12) -> 280.72292 | E3: =((('DCF_ADBE'!$B$3*(1+'DCF_ADBE'!$B$4)^1*('DCF_ADBE'!$B$5*(1-'DCF_ADBE'!$B$6)+'DCF_ADBE'!$B$7-'DCF_ADBE'!$B$8)-'DCF_ADBE'!$B$3*(1+'DCF_ADBE'!$B$4)^0*'DCF_ADBE'!$B$4*'DCF_ADBE'!$B$9)/(1+0.09000000000000001)^1+('DCF_ADBE'!$B$3*(1+'DCF_ADBE'!$B$4)^2*('DCF_ADBE'!$B$5*(1-'DCF_ADBE'!$B$6)+'DCF_ADBE'!$B$7-'DCF_ADBE'!$B$8)-'DCF_ADBE'!$B$3*(1+'DCF_ADBE'!$B$4)^1*'DCF_ADBE'!$B$4*'DCF_ADBE'!$B$9)/(1+0.09000000000000001)^2+('DCF_ADBE'!$B$3*(1+'DCF_ADBE'!$B$4)^3*('DCF_ADBE'!$B$5*(1-'DCF_ADBE'!$B$6)+'DCF_ADBE'!$B$7-'DCF_ADBE'!$B$8)-'DCF_ADBE'!$B$3*(1+'DCF_ADBE'!$B$4)^2*'DCF_ADBE'!$B$4*'DCF_ADBE'!$B$9)/(1+0.09000000000000001)^3+('DCF_ADBE'!$B$3*(1+'DCF_ADBE'!$B$4)^4*('DCF_ADBE'!$B$5*(1-'DCF_ADBE'!$B$6)+'DCF_ADBE'!$B$7-'DCF_ADBE'!$B$8)-'DCF_ADBE'!$B$3*(1+'DCF_ADBE'!$B$4)^3*'DCF_ADBE'!$B$4*'DCF_ADBE'!$B$9)/(1+0.09000000000000001)^4+('DCF_ADBE'!$B$3*(1+'DCF_ADBE'!$B$4)^5*('DCF_ADBE'!$B$5*(1-'DCF_ADBE'!$B$6)+'DCF_ADBE'!$B$7-'DCF_ADBE'!$B$8)-'DCF_ADBE'!$B$3*(1+'DCF_ADBE'!$B$4)^4*'DCF_ADBE'!$B$4*'DCF_ADBE'!$B$9)/(1+0.09000000000000001)^5+('DCF_ADBE'!$B$3*(1+'DCF_ADBE'!$B$4)^5*(1+0.025)*('DCF_ADBE'!$B$5*(1-'DCF_ADBE'!$B$6)+'DCF_ADBE'!$B$7-'DCF_ADBE'!$B$8)-'DCF_ADBE'!$B$3*(1+'DCF_ADBE'!$B$4)^5*0.025*'DCF_ADBE'!$B$9)/(0.09000000000000001-0.025)/(1+0.09000000000000001)^5-'DCF_ADBE'!$B$13)/'DCF_ADBE'!$B$12) -> 297.59053 | F3: =((('DCF_ADBE'!$B$3*(1+'DCF_ADBE'!$B$4)^1*('DCF_ADBE'!$B$5*(1-'DCF_ADBE'!$B$6)+'DCF_ADBE'!$B$7-'DCF_ADBE'!$B$8)-'DCF_ADBE'!$B$3*(1+'DCF_ADBE'!$B$4)^0*'DCF_ADBE'!$B$4*'DCF_ADBE'!$B$9)/(1+0.09000000000000001)^1+('DCF_ADBE'!$B$3*(1+'DCF_ADBE'!$B$4)^2*('DCF_ADBE'!$B$5*(1-'DCF_ADBE'!$B$6)+'DCF_ADBE'!$B$7-'DCF_ADBE'!$B$8)-'DCF_ADBE'!$B$3*(1+'DCF_ADBE'!$B$4)^1*'DCF_ADBE'!$B$4*'DCF_ADBE'!$B$9)/(1+0.09000000000000001)^2+('DCF_ADBE'!$B$3*(1+'DCF_ADBE'!$B$4)^3*('DCF_ADBE'!$B$5*(1-'DCF_ADBE'!$B$6)+'DCF_ADBE'!$B$7-'DCF_ADBE'!$B$8)-'DCF_ADBE'!$B$3*(1+'DCF_ADBE'!$B$4)^2*'DCF_ADBE'!$B$4*'DCF_ADBE'!$B$9)/(1+0.09000000000000001)^3+('DCF_ADBE'!$B$3*(1+'DCF_ADBE'!$B$4)^4*('DCF_ADBE'!$B$5*(1-'DCF_ADBE'!$B$6)+'DCF_ADBE'!$B$7-'DCF_ADBE'!$B$8)-'DCF_ADBE'!$B$3*(1+'DCF_ADBE'!$B$4)^3*'DCF_ADBE'!$B$4*'DCF_ADBE'!$B$9)/(1+0.09000000000000001)^4+('DCF_ADBE'!$B$3*(1+'DCF_ADBE'!$B$4)^5*('DCF_ADBE'!$B$5*(1-'DCF_ADBE'!$B$6)+'DCF_ADBE'!$B$7-'DCF_ADBE'!$B$8)-'DCF_ADBE'!$B$3*(1+'DCF_ADBE'!$B$4)^4*'DCF_ADBE'!$B$4*'DCF_ADBE'!$B$9)/(1+0.09000000000000001)^5+('DCF_ADBE'!$B$3*(1+'DCF_ADBE'!$B$4)^5*(1+0.030000000000000002)*('DCF_ADBE'!$B$5*(1-'DCF_ADBE'!$B$6)+'DCF_ADBE'!$B$7-'DCF_ADBE'!$B$8)-'DCF_ADBE'!$B$3*(1+'DCF_ADBE'!$B$4)^5*0.030000000000000002*'DCF_ADBE'!$B$9)/(0.09000000000000001-0.030000000000000002)/(1+0.09000000000000001)^5-'DCF_ADBE'!$B$13)/'DCF_ADBE'!$B$12) -> 317.2694 | G3: =((('DCF_ADBE'!$B$3*(1+'DCF_ADBE'!$B$4)^1*('DCF_ADBE'!$B$5*(1-'DCF_ADBE'!$B$6)+'DCF_ADBE'!$B$7-'DCF_ADBE'!$B$8)-'DCF_ADBE'!$B$3*(1+'DCF_ADBE'!$B$4)^0*'DCF_ADBE'!$B$4*'DCF_ADBE'!$B$9)/(1+0.09000000000000001)^1+('DCF_ADBE'!$B$3*(1+'DCF_ADBE'!$B$4)^2*('DCF_ADBE'!$B$5*(1-'DCF_ADBE'!$B$6)+'DCF_ADBE'!$B$7-'DCF_ADBE'!$B$8)-'DCF_ADBE'!$B$3*(1+'DCF_ADBE'!$B$4)^1*'DCF_ADBE'!$B$4*'DCF_ADBE'!$B$9)/(1+0.09000000000000001)^2+('DCF_ADBE'!$B$3*(1+'DCF_ADBE'!$B$4)^3*('DCF_ADBE'!$B$5*(1-'DCF_ADBE'!$B$6)+'DCF_ADBE'!$B$7-'DCF_ADBE'!$B$8)-'DCF_ADBE'!$B$3*(1+'DCF_ADBE'!$B$4)^2*'DCF_ADBE'!$B$4*'DCF_ADBE'!$B$9)/(1+0.09000000000000001)^3+('DCF_ADBE'!$B$3*(1+'DCF_ADBE'!$B$4)^4*('DCF_ADBE'!$B$5*(1-'DCF_ADBE'!$B$6)+'DCF_ADBE'!$B$7-'DCF_ADBE'!$B$8)-'DCF_ADBE'!$B$3*(1+'DCF_ADBE'!$B$4)^3*'DCF_ADBE'!$B$4*'DCF_ADBE'!$B$9)/(1+0.09000000000000001)^4+('DCF_ADBE'!$B$3*(1+'DCF_ADBE'!$B$4)^5*('DCF_ADBE'!$B$5*(1-'DCF_ADBE'!$B$6)+'DCF_ADBE'!$B$7-'DCF_ADBE'!$B$8)-'DCF_ADBE'!$B$3*(1+'DCF_ADBE'!$B$4)^4*'DCF_ADBE'!$B$4*'DCF_ADBE'!$B$9)/(1+0.09000000000000001)^5+('DCF_ADBE'!$B$3*(1+'DCF_ADBE'!$B$4)^5*(1+0.035)*('DCF_ADBE'!$B$5*(1-'DCF_ADBE'!$B$6)+'DCF_ADBE'!$B$7-'DCF_ADBE'!$B$8)-'DCF_ADBE'!$B$3*(1+'DCF_ADBE'!$B$4)^5*0.035*'DCF_ADBE'!$B$9)/(0.09000000000000001-0.035)/(1+0.09000000000000001)^5-'DCF_ADBE'!$B$13)/'DCF_ADBE'!$B$12) -> 340.52625
A4: ADBE | B4: 0.095 | C4: =((('DCF_ADBE'!$B$3*(1+'DCF_ADBE'!$B$4)^1*('DCF_ADBE'!$B$5*(1-'DCF_ADBE'!$B$6)+'DCF_ADBE'!$B$7-'DCF_ADBE'!$B$8)-'DCF_ADBE'!$B$3*(1+'DCF_ADBE'!$B$4)^0*'DCF_ADBE'!$B$4*'DCF_ADBE'!$B$9)/(1+0.095)^1+('DCF_ADBE'!$B$3*(1+'DCF_ADBE'!$B$4)^2*('DCF_ADBE'!$B$5*(1-'DCF_ADBE'!$B$6)+'DCF_ADBE'!$B$7-'DCF_ADBE'!$B$8)-'DCF_ADBE'!$B$3*(1+'DCF_ADBE'!$B$4)^1*'DCF_ADBE'!$B$4*'DCF_ADBE'!$B$9)/(1+0.095)^2+('DCF_ADBE'!$B$3*(1+'DCF_ADBE'!$B$4)^3*('DCF_ADBE'!$B$5*(1-'DCF_ADBE'!$B$6)+'DCF_ADBE'!$B$7-'DCF_ADBE'!$B$8)-'DCF_ADBE'!$B$3*(1+'DCF_ADBE'!$B$4)^2*'DCF_ADBE'!$B$4*'DCF_ADBE'!$B$9)/(1+0.095)^3+('DCF_ADBE'!$B$3*(1+'DCF_ADBE'!$B$4)^4*('DCF_ADBE'!$B$5*(1-'DCF_ADBE'!$B$6)+'DCF_ADBE'!$B$7-'DCF_ADBE'!$B$8)-'DCF_ADBE'!$B$3*(1+'DCF_ADBE'!$B$4)^3*'DCF_ADBE'!$B$4*'DCF_ADBE'!$B$9)/(1+0.095)^4+('DCF_ADBE'!$B$3*(1+'DCF_ADBE'!$B$4)^5*('DCF_ADBE'!$B$5*(1-'DCF_ADBE'!$B$6)+'DCF_ADBE'!$B$7-'DCF_ADBE'!$B$8)-'DCF_ADBE'!$B$3*(1+'DCF_ADBE'!$B$4)^4*'DCF_ADBE'!$B$4*'DCF_ADBE'!$B$9)/(1+0.095)^5+('DCF_ADBE'!$B$3*(1+'DCF_ADBE'!$B$4)^5*(1+0.015000000000000001)*('DCF_ADBE'!$B$5*(1-'DCF_ADBE'!$B$6)+'DCF_ADBE'!$B$7-'DCF_ADBE'!$B$8)-'DCF_ADBE'!$B$3*(1+'DCF_ADBE'!$B$4)^5*0.015000000000000001*'DCF_ADBE'!$B$9)/(0.095-0.015000000000000001)/(1+0.095)^5-'DCF_ADBE'!$B$13)/'DCF_ADBE'!$B$12) -> 249.04942 | D4: =((('DCF_ADBE'!$B$3*(1+'DCF_ADBE'!$B$4)^1*('DCF_ADBE'!$B$5*(1-'DCF_ADBE'!$B$6)+'DCF_ADBE'!$B$7-'DCF_ADBE'!$B$8)-'DCF_ADBE'!$B$3*(1+'DCF_ADBE'!$B$4)^0*'DCF_ADBE'!$B$4*'DCF_ADBE'!$B$9)/(1+0.095)^1+('DCF_ADBE'!$B$3*(1+'DCF_ADBE'!$B$4)^2*('DCF_ADBE'!$B$5*(1-'DCF_ADBE'!$B$6)+'DCF_ADBE'!$B$7-'DCF_ADBE'!$B$8)-'DCF_ADBE'!$B$3*(1+'DCF_ADBE'!$B$4)^1*'DCF_ADBE'!$B$4*'DCF_ADBE'!$B$9)/(1+0.095)^2+('DCF_ADBE'!$B$3*(1+'DCF_ADBE'!$B$4)^3*('DCF_ADBE'!$B$5*(1-'DCF_ADBE'!$B$6)+'DCF_ADBE'!$B$7-'DCF_ADBE'!$B$8)-'DCF_ADBE'!$B$3*(1+'DCF_ADBE'!$B$4)^2*'DCF_ADBE'!$B$4*'DCF_ADBE'!$B$9)/(1+0.095)^3+('DCF_ADBE'!$B$3*(1+'DCF_ADBE'!$B$4)^4*('DCF_ADBE'!$B$5*(1-'DCF_ADBE'!$B$6)+'DCF_ADBE'!$B$7-'DCF_ADBE'!$B$8)-'DCF_ADBE'!$B$3*(1+'DCF_ADBE'!$B$4)^3*'DCF_ADBE'!$B$4*'DCF_ADBE'!$B$9)/(1+0.095)^4+('DCF_ADBE'!$B$3*(1+'DCF_ADBE'!$B$4)^5*('DCF_ADBE'!$B$5*(1-'DCF_ADBE'!$B$6)+'DCF_ADBE'!$B$7-'DCF_ADBE'!$B$8)-'DCF_ADBE'!$B$3*(1+'DCF_ADBE'!$B$4)^4*'DCF_ADBE'!$B$4*'DCF_ADBE'!$B$9)/(1+0.095)^5+('DCF_ADBE'!$B$3*(1+'DCF_ADBE'!$B$4)^5*(1+0.02)*('DCF_ADBE'!$B$5*(1-'DCF_ADBE'!$B$6)+'DCF_ADBE'!$B$7-'DCF_ADBE'!$B$8)-'DCF_ADBE'!$B$3*(1+'DCF_ADBE'!$B$4)^5*0.02*'DCF_ADBE'!$B$9)/(0.095-0.02)/(1+0.095)^5-'DCF_ADBE'!$B$13)/'DCF_ADBE'!$B$12) -> 261.60297 | E4: =((('DCF_ADBE'!$B$3*(1+'DCF_ADBE'!$B$4)^1*('DCF_ADBE'!$B$5*(1-'DCF_ADBE'!$B$6)+'DCF_ADBE'!$B$7-'DCF_ADBE'!$B$8)-'DCF_ADBE'!$B$3*(1+'DCF_ADBE'!$B$4)^0*'DCF_ADBE'!$B$4*'DCF_ADBE'!$B$9)/(1+0.095)^1+('DCF_ADBE'!$B$3*(1+'DCF_ADBE'!$B$4)^2*('DCF_ADBE'!$B$5*(1-'DCF_ADBE'!$B$6)+'DCF_ADBE'!$B$7-'DCF_ADBE'!$B$8)-'DCF_ADBE'!$B$3*(1+'DCF_ADBE'!$B$4)^1*'DCF_ADBE'!$B$4*'DCF_ADBE'!$B$9)/(1+0.095)^2+('DCF_ADBE'!$B$3*(1+'DCF_ADBE'!$B$4)^3*('DCF_ADBE'!$B$5*(1-'DCF_ADBE'!$B$6)+'DCF_ADBE'!$B$7-'DCF_ADBE'!$B$8)-'DCF_ADBE'!$B$3*(1+'DCF_ADBE'!$B$4)^2*'DCF_ADBE'!$B$4*'DCF_ADBE'!$B$9)/(1+0.095)^3+('DCF_ADBE'!$B$3*(1+'DCF_ADBE'!$B$4)^4*('DCF_ADBE'!$B$5*(1-'DCF_ADBE'!$B$6)+'DCF_ADBE'!$B$7-'DCF_ADBE'!$B$8)-'DCF_ADBE'!$B$3*(1+'DCF_ADBE'!$B$4)^3*'DCF_ADBE'!$B$4*'DCF_ADBE'!$B$9)/(1+0.095)^4+('DCF_ADBE'!$B$3*(1+'DCF_ADBE'!$B$4)^5*('DCF_ADBE'!$B$5*(1-'DCF_ADBE'!$B$6)+'DCF_ADBE'!$B$7-'DCF_ADBE'!$B$8)-'DCF_ADBE'!$B$3*(1+'DCF_ADBE'!$B$4)^4*'DCF_ADBE'!$B$4*'DCF_ADBE'!$B$9)/(1+0.095)^5+('DCF_ADBE'!$B$3*(1+'DCF_ADBE'!$B$4)^5*(1+0.025)*('DCF_ADBE'!$B$5*(1-'DCF_ADBE'!$B$6)+'DCF_ADBE'!$B$7-'DCF_ADBE'!$B$8)-'DCF_ADBE'!$B$3*(1+'DCF_ADBE'!$B$4)^5*0.025*'DCF_ADBE'!$B$9)/(0.095-0.025)/(1+0.095)^5-'DCF_ADBE'!$B$13)/'DCF_ADBE'!$B$12) -> 275.94988 | F4: =((('DCF_ADBE'!$B$3*(1+'DCF_ADBE'!$B$4)^1*('DCF_ADBE'!$B$5*(1-'DCF_ADBE'!$B$6)+'DCF_ADBE'!$B$7-'DCF_ADBE'!$B$8)-'DCF_ADBE'!$B$3*(1+'DCF_ADBE'!$B$4)^0*'DCF_ADBE'!$B$4*'DCF_ADBE'!$B$9)/(1+0.095)^1+('DCF_ADBE'!$B$3*(1+'DCF_ADBE'!$B$4)^2*('DCF_ADBE'!$B$5*(1-'DCF_ADBE'!$B$6)+'DCF_ADBE'!$B$7-'DCF_ADBE'!$B$8)-'DCF_ADBE'!$B$3*(1+'DCF_ADBE'!$B$4)^1*'DCF_ADBE'!$B$4*'DCF_ADBE'!$B$9)/(1+0.095)^2+('DCF_ADBE'!$B$3*(1+'DCF_ADBE'!$B$4)^3*('DCF_ADBE'!$B$5*(1-'DCF_ADBE'!$B$6)+'DCF_ADBE'!$B$7-'DCF_ADBE'!$B$8)-'DCF_ADBE'!$B$3*(1+'DCF_ADBE'!$B$4)^2*'DCF_ADBE'!$B$4*'DCF_ADBE'!$B$9)/(1+0.095)^3+('DCF_ADBE'!$B$3*(1+'DCF_ADBE'!$B$4)^4*('DCF_ADBE'!$B$5*(1-'DCF_ADBE'!$B$6)+'DCF_ADBE'!$B$7-'DCF_ADBE'!$B$8)-'DCF_ADBE'!$B$3*(1+'DCF_ADBE'!$B$4)^3*'DCF_ADBE'!$B$4*'DCF_ADBE'!$B$9)/(1+0.095)^4+('DCF_ADBE'!$B$3*(1+'DCF_ADBE'!$B$4)^5*('DCF_ADBE'!$B$5*(1-'DCF_ADBE'!$B$6)+'DCF_ADBE'!$B$7-'DCF_ADBE'!$B$8)-'DCF_ADBE'!$B$3*(1+'DCF_ADBE'!$B$4)^4*'DCF_ADBE'!$B$4*'DCF_ADBE'!$B$9)/(1+0.095)^5+('DCF_ADBE'!$B$3*(1+'DCF_ADBE'!$B$4)^5*(1+0.030000000000000002)*('DCF_ADBE'!$B$5*(1-'DCF_ADBE'!$B$6)+'DCF_ADBE'!$B$7-'DCF_ADBE'!$B$8)-'DCF_ADBE'!$B$3*(1+'DCF_ADBE'!$B$4)^5*0.030000000000000002*'DCF_ADBE'!$B$9)/(0.095-0.030000000000000002)/(1+0.095)^5-'DCF_ADBE'!$B$13)/'DCF_ADBE'!$B$12) -> 292.504 | G4: =((('DCF_ADBE'!$B$3*(1+'DCF_ADBE'!$B$4)^1*('DCF_ADBE'!$B$5*(1-'DCF_ADBE'!$B$6)+'DCF_ADBE'!$B$7-'DCF_ADBE'!$B$8)-'DCF_ADBE'!$B$3*(1+'DCF_ADBE'!$B$4)^0*'DCF_ADBE'!$B$4*'DCF_ADBE'!$B$9)/(1+0.095)^1+('DCF_ADBE'!$B$3*(1+'DCF_ADBE'!$B$4)^2*('DCF_ADBE'!$B$5*(1-'DCF_ADBE'!$B$6)+'DCF_ADBE'!$B$7-'DCF_ADBE'!$B$8)-'DCF_ADBE'!$B$3*(1+'DCF_ADBE'!$B$4)^1*'DCF_ADBE'!$B$4*'DCF_ADBE'!$B$9)/(1+0.095)^2+('DCF_ADBE'!$B$3*(1+'DCF_ADBE'!$B$4)^3*('DCF_ADBE'!$B$5*(1-'DCF_ADBE'!$B$6)+'DCF_ADBE'!$B$7-'DCF_ADBE'!$B$8)-'DCF_ADBE'!$B$3*(1+'DCF_ADBE'!$B$4)^2*'DCF_ADBE'!$B$4*'DCF_ADBE'!$B$9)/(1+0.095)^3+('DCF_ADBE'!$B$3*(1+'DCF_ADBE'!$B$4)^4*('DCF_ADBE'!$B$5*(1-'DCF_ADBE'!$B$6)+'DCF_ADBE'!$B$7-'DCF_ADBE'!$B$8)-'DCF_ADBE'!$B$3*(1+'DCF_ADBE'!$B$4)^3*'DCF_ADBE'!$B$4*'DCF_ADBE'!$B$9)/(1+0.095)^4+('DCF_ADBE'!$B$3*(1+'DCF_ADBE'!$B$4)^5*('DCF_ADBE'!$B$5*(1-'DCF_ADBE'!$B$6)+'DCF_ADBE'!$B$7-'DCF_ADBE'!$B$8)-'DCF_ADBE'!$B$3*(1+'DCF_ADBE'!$B$4)^4*'DCF_ADBE'!$B$4*'DCF_ADBE'!$B$9)/(1+0.095)^5+('DCF_ADBE'!$B$3*(1+'DCF_ADBE'!$B$4)^5*(1+0.035)*('DCF_ADBE'!$B$5*(1-'DCF_ADBE'!$B$6)+'DCF_ADBE'!$B$7-'DCF_ADBE'!$B$8)-'DCF_ADBE'!$B$3*(1+'DCF_ADBE'!$B$4)^5*0.035*'DCF_ADBE'!$B$9)/(0.095-0.035)/(1+0.095)^5-'DCF_ADBE'!$B$13)/'DCF_ADBE'!$B$12) -> 311.81715
A5: ADBE | B5: 0.1 | C5: =((('DCF_ADBE'!$B$3*(1+'DCF_ADBE'!$B$4)^1*('DCF_ADBE'!$B$5*(1-'DCF_ADBE'!$B$6)+'DCF_ADBE'!$B$7-'DCF_ADBE'!$B$8)-'DCF_ADBE'!$B$3*(1+'DCF_ADBE'!$B$4)^0*'DCF_ADBE'!$B$4*'DCF_ADBE'!$B$9)/(1+0.1)^1+('DCF_ADBE'!$B$3*(1+'DCF_ADBE'!$B$4)^2*('DCF_ADBE'!$B$5*(1-'DCF_ADBE'!$B$6)+'DCF_ADBE'!$B$7-'DCF_ADBE'!$B$8)-'DCF_ADBE'!$B$3*(1+'DCF_ADBE'!$B$4)^1*'DCF_ADBE'!$B$4*'DCF_ADBE'!$B$9)/(1+0.1)^2+('DCF_ADBE'!$B$3*(1+'DCF_ADBE'!$B$4)^3*('DCF_ADBE'!$B$5*(1-'DCF_ADBE'!$B$6)+'DCF_ADBE'!$B$7-'DCF_ADBE'!$B$8)-'DCF_ADBE'!$B$3*(1+'DCF_ADBE'!$B$4)^2*'DCF_ADBE'!$B$4*'DCF_ADBE'!$B$9)/(1+0.1)^3+('DCF_ADBE'!$B$3*(1+'DCF_ADBE'!$B$4)^4*('DCF_ADBE'!$B$5*(1-'DCF_ADBE'!$B$6)+'DCF_ADBE'!$B$7-'DCF_ADBE'!$B$8)-'DCF_ADBE'!$B$3*(1+'DCF_ADBE'!$B$4)^3*'DCF_ADBE'!$B$4*'DCF_ADBE'!$B$9)/(1+0.1)^4+('DCF_ADBE'!$B$3*(1+'DCF_ADBE'!$B$4)^5*('DCF_ADBE'!$B$5*(1-'DCF_ADBE'!$B$6)+'DCF_ADBE'!$B$7-'DCF_ADBE'!$B$8)-'DCF_ADBE'!$B$3*(1+'DCF_ADBE'!$B$4)^4*'DCF_ADBE'!$B$4*'DCF_ADBE'!$B$9)/(1+0.1)^5+('DCF_ADBE'!$B$3*(1+'DCF_ADBE'!$B$4)^5*(1+0.015000000000000001)*('DCF_ADBE'!$B$5*(1-'DCF_ADBE'!$B$6)+'DCF_ADBE'!$B$7-'DCF_ADBE'!$B$8)-'DCF_ADBE'!$B$3*(1+'DCF_ADBE'!$B$4)^5*0.015000000000000001*'DCF_ADBE'!$B$9)/(0.1-0.015000000000000001)/(1+0.1)^5-'DCF_ADBE'!$B$13)/'DCF_ADBE'!$B$12) -> 234.00929 | D5: =((('DCF_ADBE'!$B$3*(1+'DCF_ADBE'!$B$4)^1*('DCF_ADBE'!$B$5*(1-'DCF_ADBE'!$B$6)+'DCF_ADBE'!$B$7-'DCF_ADBE'!$B$8)-'DCF_ADBE'!$B$3*(1+'DCF_ADBE'!$B$4)^0*'DCF_ADBE'!$B$4*'DCF_ADBE'!$B$9)/(1+0.1)^1+('DCF_ADBE'!$B$3*(1+'DCF_ADBE'!$B$4)^2*('DCF_ADBE'!$B$5*(1-'DCF_ADBE'!$B$6)+'DCF_ADBE'!$B$7-'DCF_ADBE'!$B$8)-'DCF_ADBE'!$B$3*(1+'DCF_ADBE'!$B$4)^1*'DCF_ADBE'!$B$4*'DCF_ADBE'!$B$9)/(1+0.1)^2+('DCF_ADBE'!$B$3*(1+'DCF_ADBE'!$B$4)^3*('DCF_ADBE'!$B$5*(1-'DCF_ADBE'!$B$6)+'DCF_ADBE'!$B$7-'DCF_ADBE'!$B$8)-'DCF_ADBE'!$B$3*(1+'DCF_ADBE'!$B$4)^2*'DCF_ADBE'!$B$4*'DCF_ADBE'!$B$9)/(1+0.1)^3+('DCF_ADBE'!$B$3*(1+'DCF_ADBE'!$B$4)^4*('DCF_ADBE'!$B$5*(1-'DCF_ADBE'!$B$6)+'DCF_ADBE'!$B$7-'DCF_ADBE'!$B$8)-'DCF_ADBE'!$B$3*(1+'DCF_ADBE'!$B$4)^3*'DCF_ADBE'!$B$4*'DCF_ADBE'!$B$9)/(1+0.1)^4+('DCF_ADBE'!$B$3*(1+'DCF_ADBE'!$B$4)^5*('DCF_ADBE'!$B$5*(1-'DCF_ADBE'!$B$6)+'DCF_ADBE'!$B$7-'DCF_ADBE'!$B$8)-'DCF_ADBE'!$B$3*(1+'DCF_ADBE'!$B$4)^4*'DCF_ADBE'!$B$4*'DCF_ADBE'!$B$9)/(1+0.1)^5+('DCF_ADBE'!$B$3*(1+'DCF_ADBE'!$B$4)^5*(1+0.02)*('DCF_ADBE'!$B$5*(1-'DCF_ADBE'!$B$6)+'DCF_ADBE'!$B$7-'DCF_ADBE'!$B$8)-'DCF_ADBE'!$B$3*(1+'DCF_ADBE'!$B$4)^5*0.02*'DCF_ADBE'!$B$9)/(0.1-0.02)/(1+0.1)^5-'DCF_ADBE'!$B$13)/'DCF_ADBE'!$B$12) -> 244.88104 | E5: =((('DCF_ADBE'!$B$3*(1+'DCF_ADBE'!$B$4)^1*('DCF_ADBE'!$B$5*(1-'DCF_ADBE'!$B$6)+'DCF_ADBE'!$B$7-'DCF_ADBE'!$B$8)-'DCF_ADBE'!$B$3*(1+'DCF_ADBE'!$B$4)^0*'DCF_ADBE'!$B$4*'DCF_ADBE'!$B$9)/(1+0.1)^1+('DCF_ADBE'!$B$3*(1+'DCF_ADBE'!$B$4)^2*('DCF_ADBE'!$B$5*(1-'DCF_ADBE'!$B$6)+'DCF_ADBE'!$B$7-'DCF_ADBE'!$B$8)-'DCF_ADBE'!$B$3*(1+'DCF_ADBE'!$B$4)^1*'DCF_ADBE'!$B$4*'DCF_ADBE'!$B$9)/(1+0.1)^2+('DCF_ADBE'!$B$3*(1+'DCF_ADBE'!$B$4)^3*('DCF_ADBE'!$B$5*(1-'DCF_ADBE'!$B$6)+'DCF_ADBE'!$B$7-'DCF_ADBE'!$B$8)-'DCF_ADBE'!$B$3*(1+'DCF_ADBE'!$B$4)^2*'DCF_ADBE'!$B$4*'DCF_ADBE'!$B$9)/(1+0.1)^3+('DCF_ADBE'!$B$3*(1+'DCF_ADBE'!$B$4)^4*('DCF_ADBE'!$B$5*(1-'DCF_ADBE'!$B$6)+'DCF_ADBE'!$B$7-'DCF_ADBE'!$B$8)-'DCF_ADBE'!$B$3*(1+'DCF_ADBE'!$B$4)^3*'DCF_ADBE'!$B$4*'DCF_ADBE'!$B$9)/(1+0.1)^4+('DCF_ADBE'!$B$3*(1+'DCF_ADBE'!$B$4)^5*('DCF_ADBE'!$B$5*(1-'DCF_ADBE'!$B$6)+'DCF_ADBE'!$B$7-'DCF_ADBE'!$B$8)-'DCF_ADBE'!$B$3*(1+'DCF_ADBE'!$B$4)^4*'DCF_ADBE'!$B$4*'DCF_ADBE'!$B$9)/(1+0.1)^5+('DCF_ADBE'!$B$3*(1+'DCF_ADBE'!$B$4)^5*(1+0.025)*('DCF_ADBE'!$B$5*(1-'DCF_ADBE'!$B$6)+'DCF_ADBE'!$B$7-'DCF_ADBE'!$B$8)-'DCF_ADBE'!$B$3*(1+'DCF_ADBE'!$B$4)^5*0.025*'DCF_ADBE'!$B$9)/(0.1-0.025)/(1+0.1)^5-'DCF_ADBE'!$B$13)/'DCF_ADBE'!$B$12) -> 257.20235 | F5: =((('DCF_ADBE'!$B$3*(1+'DCF_ADBE'!$B$4)^1*('DCF_ADBE'!$B$5*(1-'DCF_ADBE'!$B$6)+'DCF_ADBE'!$B$7-'DCF_ADBE'!$B$8)-'DCF_ADBE'!$B$3*(1+'DCF_ADBE'!$B$4)^0*'DCF_ADBE'!$B$4*'DCF_ADBE'!$B$9)/(1+0.1)^1+('DCF_ADBE'!$B$3*(1+'DCF_ADBE'!$B$4)^2*('DCF_ADBE'!$B$5*(1-'DCF_ADBE'!$B$6)+'DCF_ADBE'!$B$7-'DCF_ADBE'!$B$8)-'DCF_ADBE'!$B$3*(1+'DCF_ADBE'!$B$4)^1*'DCF_ADBE'!$B$4*'DCF_ADBE'!$B$9)/(1+0.1)^2+('DCF_ADBE'!$B$3*(1+'DCF_ADBE'!$B$4)^3*('DCF_ADBE'!$B$5*(1-'DCF_ADBE'!$B$6)+'DCF_ADBE'!$B$7-'DCF_ADBE'!$B$8)-'DCF_ADBE'!$B$3*(1+'DCF_ADBE'!$B$4)^2*'DCF_ADBE'!$B$4*'DCF_ADBE'!$B$9)/(1+0.1)^3+('DCF_ADBE'!$B$3*(1+'DCF_ADBE'!$B$4)^4*('DCF_ADBE'!$B$5*(1-'DCF_ADBE'!$B$6)+'DCF_ADBE'!$B$7-'DCF_ADBE'!$B$8)-'DCF_ADBE'!$B$3*(1+'DCF_ADBE'!$B$4)^3*'DCF_ADBE'!$B$4*'DCF_ADBE'!$B$9)/(1+0.1)^4+('DCF_ADBE'!$B$3*(1+'DCF_ADBE'!$B$4)^5*('DCF_ADBE'!$B$5*(1-'DCF_ADBE'!$B$6)+'DCF_ADBE'!$B$7-'DCF_ADBE'!$B$8)-'DCF_ADBE'!$B$3*(1+'DCF_ADBE'!$B$4)^4*'DCF_ADBE'!$B$4*'DCF_ADBE'!$B$9)/(1+0.1)^5+('DCF_ADBE'!$B$3*(1+'DCF_ADBE'!$B$4)^5*(1+0.030000000000000002)*('DCF_ADBE'!$B$5*(1-'DCF_ADBE'!$B$6)+'DCF_ADBE'!$B$7-'DCF_ADBE'!$B$8)-'DCF_ADBE'!$B$3*(1+'DCF_ADBE'!$B$4)^5*0.030000000000000002*'DCF_ADBE'!$B$9)/(0.1-0.030000000000000002)/(1+0.1)^5-'DCF_ADBE'!$B$13)/'DCF_ADBE'!$B$12) -> 271.28386 | G5: =((('DCF_ADBE'!$B$3*(1+'DCF_ADBE'!$B$4)^1*('DCF_ADBE'!$B$5*(1-'DCF_ADBE'!$B$6)+'DCF_ADBE'!$B$7-'DCF_ADBE'!$B$8)-'DCF_ADBE'!$B$3*(1+'DCF_ADBE'!$B$4)^0*'DCF_ADBE'!$B$4*'DCF_ADBE'!$B$9)/(1+0.1)^1+('DCF_ADBE'!$B$3*(1+'DCF_ADBE'!$B$4)^2*('DCF_ADBE'!$B$5*(1-'DCF_ADBE'!$B$6)+'DCF_ADBE'!$B$7-'DCF_ADBE'!$B$8)-'DCF_ADBE'!$B$3*(1+'DCF_ADBE'!$B$4)^1*'DCF_ADBE'!$B$4*'DCF_ADBE'!$B$9)/(1+0.1)^2+('DCF_ADBE'!$B$3*(1+'DCF_ADBE'!$B$4)^3*('DCF_ADBE'!$B$5*(1-'DCF_ADBE'!$B$6)+'DCF_ADBE'!$B$7-'DCF_ADBE'!$B$8)-'DCF_ADBE'!$B$3*(1+'DCF_ADBE'!$B$4)^2*'DCF_ADBE'!$B$4*'DCF_ADBE'!$B$9)/(1+0.1)^3+('DCF_ADBE'!$B$3*(1+'DCF_ADBE'!$B$4)^4*('DCF_ADBE'!$B$5*(1-'DCF_ADBE'!$B$6)+'DCF_ADBE'!$B$7-'DCF_ADBE'!$B$8)-'DCF_ADBE'!$B$3*(1+'DCF_ADBE'!$B$4)^3*'DCF_ADBE'!$B$4*'DCF_ADBE'!$B$9)/(1+0.1)^4+('DCF_ADBE'!$B$3*(1+'DCF_ADBE'!$B$4)^5*('DCF_ADBE'!$B$5*(1-'DCF_ADBE'!$B$6)+'DCF_ADBE'!$B$7-'DCF_ADBE'!$B$8)-'DCF_ADBE'!$B$3*(1+'DCF_ADBE'!$B$4)^4*'DCF_ADBE'!$B$4*'DCF_ADBE'!$B$9)/(1+0.1)^5+('DCF_ADBE'!$B$3*(1+'DCF_ADBE'!$B$4)^5*(1+0.035)*('DCF_ADBE'!$B$5*(1-'DCF_ADBE'!$B$6)+'DCF_ADBE'!$B$7-'DCF_ADBE'!$B$8)-'DCF_ADBE'!$B$3*(1+'DCF_ADBE'!$B$4)^5*0.035*'DCF_ADBE'!$B$9)/(0.1-0.035)/(1+0.1)^5-'DCF_ADBE'!$B$13)/'DCF_ADBE'!$B$12) -> 287.53175
A6: ADBE | B6: 0.105 | C6: =((('DCF_ADBE'!$B$3*(1+'DCF_ADBE'!$B$4)^1*('DCF_ADBE'!$B$5*(1-'DCF_ADBE'!$B$6)+'DCF_ADBE'!$B$7-'DCF_ADBE'!$B$8)-'DCF_ADBE'!$B$3*(1+'DCF_ADBE'!$B$4)^0*'DCF_ADBE'!$B$4*'DCF_ADBE'!$B$9)/(1+0.10500000000000001)^1+('DCF_ADBE'!$B$3*(1+'DCF_ADBE'!$B$4)^2*('DCF_ADBE'!$B$5*(1-'DCF_ADBE'!$B$6)+'DCF_ADBE'!$B$7-'DCF_ADBE'!$B$8)-'DCF_ADBE'!$B$3*(1+'DCF_ADBE'!$B$4)^1*'DCF_ADBE'!$B$4*'DCF_ADBE'!$B$9)/(1+0.10500000000000001)^2+('DCF_ADBE'!$B$3*(1+'DCF_ADBE'!$B$4)^3*('DCF_ADBE'!$B$5*(1-'DCF_ADBE'!$B$6)+'DCF_ADBE'!$B$7-'DCF_ADBE'!$B$8)-'DCF_ADBE'!$B$3*(1+'DCF_ADBE'!$B$4)^2*'DCF_ADBE'!$B$4*'DCF_ADBE'!$B$9)/(1+0.10500000000000001)^3+('DCF_ADBE'!$B$3*(1+'DCF_ADBE'!$B$4)^4*('DCF_ADBE'!$B$5*(1-'DCF_ADBE'!$B$6)+'DCF_ADBE'!$B$7-'DCF_ADBE'!$B$8)-'DCF_ADBE'!$B$3*(1+'DCF_ADBE'!$B$4)^3*'DCF_ADBE'!$B$4*'DCF_ADBE'!$B$9)/(1+0.10500000000000001)^4+('DCF_ADBE'!$B$3*(1+'DCF_ADBE'!$B$4)^5*('DCF_ADBE'!$B$5*(1-'DCF_ADBE'!$B$6)+'DCF_ADBE'!$B$7-'DCF_ADBE'!$B$8)-'DCF_ADBE'!$B$3*(1+'DCF_ADBE'!$B$4)^4*'DCF_ADBE'!$B$4*'DCF_ADBE'!$B$9)/(1+0.10500000000000001)^5+('DCF_ADBE'!$B$3*(1+'DCF_ADBE'!$B$4)^5*(1+0.015000000000000001)*('DCF_ADBE'!$B$5*(1-'DCF_ADBE'!$B$6)+'DCF_ADBE'!$B$7-'DCF_ADBE'!$B$8)-'DCF_ADBE'!$B$3*(1+'DCF_ADBE'!$B$4)^5*0.015000000000000001*'DCF_ADBE'!$B$9)/(0.10500000000000001-0.015000000000000001)/(1+0.10500000000000001)^5-'DCF_ADBE'!$B$13)/'DCF_ADBE'!$B$12) -> 220.64794 | D6: =((('DCF_ADBE'!$B$3*(1+'DCF_ADBE'!$B$4)^1*('DCF_ADBE'!$B$5*(1-'DCF_ADBE'!$B$6)+'DCF_ADBE'!$B$7-'DCF_ADBE'!$B$8)-'DCF_ADBE'!$B$3*(1+'DCF_ADBE'!$B$4)^0*'DCF_ADBE'!$B$4*'DCF_ADBE'!$B$9)/(1+0.10500000000000001)^1+('DCF_ADBE'!$B$3*(1+'DCF_ADBE'!$B$4)^2*('DCF_ADBE'!$B$5*(1-'DCF_ADBE'!$B$6)+'DCF_ADBE'!$B$7-'DCF_ADBE'!$B$8)-'DCF_ADBE'!$B$3*(1+'DCF_ADBE'!$B$4)^1*'DCF_ADBE'!$B$4*'DCF_ADBE'!$B$9)/(1+0.10500000000000001)^2+('DCF_ADBE'!$B$3*(1+'DCF_ADBE'!$B$4)^3*('DCF_ADBE'!$B$5*(1-'DCF_ADBE'!$B$6)+'DCF_ADBE'!$B$7-'DCF_ADBE'!$B$8)-'DCF_ADBE'!$B$3*(1+'DCF_ADBE'!$B$4)^2*'DCF_ADBE'!$B$4*'DCF_ADBE'!$B$9)/(1+0.10500000000000001)^3+('DCF_ADBE'!$B$3*(1+'DCF_ADBE'!$B$4)^4*('DCF_ADBE'!$B$5*(1-'DCF_ADBE'!$B$6)+'DCF_ADBE'!$B$7-'DCF_ADBE'!$B$8)-'DCF_ADBE'!$B$3*(1+'DCF_ADBE'!$B$4)^3*'DCF_ADBE'!$B$4*'DCF_ADBE'!$B$9)/(1+0.10500000000000001)^4+('DCF_ADBE'!$B$3*(1+'DCF_ADBE'!$B$4)^5*('DCF_ADBE'!$B$5*(1-'DCF_ADBE'!$B$6)+'DCF_ADBE'!$B$7-'DCF_ADBE'!$B$8)-'DCF_ADBE'!$B$3*(1+'DCF_ADBE'!$B$4)^4*'DCF_ADBE'!$B$4*'DCF_ADBE'!$B$9)/(1+0.10500000000000001)^5+('DCF_ADBE'!$B$3*(1+'DCF_ADBE'!$B$4)^5*(1+0.02)*('DCF_ADBE'!$B$5*(1-'DCF_ADBE'!$B$6)+'DCF_ADBE'!$B$7-'DCF_ADBE'!$B$8)-'DCF_ADBE'!$B$3*(1+'DCF_ADBE'!$B$4)^5*0.02*'DCF_ADBE'!$B$9)/(0.10500000000000001-0.02)/(1+0.10500000000000001)^5-'DCF_ADBE'!$B$13)/'DCF_ADBE'!$B$12) -> 230.13377 | E6: =((('DCF_ADBE'!$B$3*(1+'DCF_ADBE'!$B$4)^1*('DCF_ADBE'!$B$5*(1-'DCF_ADBE'!$B$6)+'DCF_ADBE'!$B$7-'DCF_ADBE'!$B$8)-'DCF_ADBE'!$B$3*(1+'DCF_ADBE'!$B$4)^0*'DCF_ADBE'!$B$4*'DCF_ADBE'!$B$9)/(1+0.10500000000000001)^1+('DCF_ADBE'!$B$3*(1+'DCF_ADBE'!$B$4)^2*('DCF_ADBE'!$B$5*(1-'DCF_ADBE'!$B$6)+'DCF_ADBE'!$B$7-'DCF_ADBE'!$B$8)-'DCF_ADBE'!$B$3*(1+'DCF_ADBE'!$B$4)^1*'DCF_ADBE'!$B$4*'DCF_ADBE'!$B$9)/(1+0.10500000000000001)^2+('DCF_ADBE'!$B$3*(1+'DCF_ADBE'!$B$4)^3*('DCF_ADBE'!$B$5*(1-'DCF_ADBE'!$B$6)+'DCF_ADBE'!$B$7-'DCF_ADBE'!$B$8)-'DCF_ADBE'!$B$3*(1+'DCF_ADBE'!$B$4)^2*'DCF_ADBE'!$B$4*'DCF_ADBE'!$B$9)/(1+0.10500000000000001)^3+('DCF_ADBE'!$B$3*(1+'DCF_ADBE'!$B$4)^4*('DCF_ADBE'!$B$5*(1-'DCF_ADBE'!$B$6)+'DCF_ADBE'!$B$7-'DCF_ADBE'!$B$8)-'DCF_ADBE'!$B$3*(1+'DCF_ADBE'!$B$4)^3*'DCF_ADBE'!$B$4*'DCF_ADBE'!$B$9)/(1+0.10500000000000001)^4+('DCF_ADBE'!$B$3*(1+'DCF_ADBE'!$B$4)^5*('DCF_ADBE'!$B$5*(1-'DCF_ADBE'!$B$6)+'DCF_ADBE'!$B$7-'DCF_ADBE'!$B$8)-'DCF_ADBE'!$B$3*(1+'DCF_ADBE'!$B$4)^4*'DCF_ADBE'!$B$4*'DCF_ADBE'!$B$9)/(1+0.10500000000000001)^5+('DCF_ADBE'!$B$3*(1+'DCF_ADBE'!$B$4)^5*(1+0.025)*('DCF_ADBE'!$B$5*(1-'DCF_ADBE'!$B$6)+'DCF_ADBE'!$B$7-'DCF_ADBE'!$B$8)-'DCF_ADBE'!$B$3*(1+'DCF_ADBE'!$B$4)^5*0.025*'DCF_ADBE'!$B$9)/(0.10500000000000001-0.025)/(1+0.10500000000000001)^5-'DCF_ADBE'!$B$13)/'DCF_ADBE'!$B$12) -> 240.80532 | F6: =((('DCF_ADBE'!$B$3*(1+'DCF_ADBE'!$B$4)^1*('DCF_ADBE'!$B$5*(1-'DCF_ADBE'!$B$6)+'DCF_ADBE'!$B$7-'DCF_ADBE'!$B$8)-'DCF_ADBE'!$B$3*(1+'DCF_ADBE'!$B$4)^0*'DCF_ADBE'!$B$4*'DCF_ADBE'!$B$9)/(1+0.10500000000000001)^1+('DCF_ADBE'!$B$3*(1+'DCF_ADBE'!$B$4)^2*('DCF_ADBE'!$B$5*(1-'DCF_ADBE'!$B$6)+'DCF_ADBE'!$B$7-'DCF_ADBE'!$B$8)-'DCF_ADBE'!$B$3*(1+'DCF_ADBE'!$B$4)^1*'DCF_ADBE'!$B$4*'DCF_ADBE'!$B$9)/(1+0.10500000000000001)^2+('DCF_ADBE'!$B$3*(1+'DCF_ADBE'!$B$4)^3*('DCF_ADBE'!$B$5*(1-'DCF_ADBE'!$B$6)+'DCF_ADBE'!$B$7-'DCF_ADBE'!$B$8)-'DCF_ADBE'!$B$3*(1+'DCF_ADBE'!$B$4)^2*'DCF_ADBE'!$B$4*'DCF_ADBE'!$B$9)/(1+0.10500000000000001)^3+('DCF_ADBE'!$B$3*(1+'DCF_ADBE'!$B$4)^4*('DCF_ADBE'!$B$5*(1-'DCF_ADBE'!$B$6)+'DCF_ADBE'!$B$7-'DCF_ADBE'!$B$8)-'DCF_ADBE'!$B$3*(1+'DCF_ADBE'!$B$4)^3*'DCF_ADBE'!$B$4*'DCF_ADBE'!$B$9)/(1+0.10500000000000001)^4+('DCF_ADBE'!$B$3*(1+'DCF_ADBE'!$B$4)^5*('DCF_ADBE'!$B$5*(1-'DCF_ADBE'!$B$6)+'DCF_ADBE'!$B$7-'DCF_ADBE'!$B$8)-'DCF_ADBE'!$B$3*(1+'DCF_ADBE'!$B$4)^4*'DCF_ADBE'!$B$4*'DCF_ADBE'!$B$9)/(1+0.10500000000000001)^5+('DCF_ADBE'!$B$3*(1+'DCF_ADBE'!$B$4)^5*(1+0.030000000000000002)*('DCF_ADBE'!$B$5*(1-'DCF_ADBE'!$B$6)+'DCF_ADBE'!$B$7-'DCF_ADBE'!$B$8)-'DCF_ADBE'!$B$3*(1+'DCF_ADBE'!$B$4)^5*0.030000000000000002*'DCF_ADBE'!$B$9)/(0.10500000000000001-0.030000000000000002)/(1+0.10500000000000001)^5-'DCF_ADBE'!$B$13)/'DCF_ADBE'!$B$12) -> 252.89975 | G6: =((('DCF_ADBE'!$B$3*(1+'DCF_ADBE'!$B$4)^1*('DCF_ADBE'!$B$5*(1-'DCF_ADBE'!$B$6)+'DCF_ADBE'!$B$7-'DCF_ADBE'!$B$8)-'DCF_ADBE'!$B$3*(1+'DCF_ADBE'!$B$4)^0*'DCF_ADBE'!$B$4*'DCF_ADBE'!$B$9)/(1+0.10500000000000001)^1+('DCF_ADBE'!$B$3*(1+'DCF_ADBE'!$B$4)^2*('DCF_ADBE'!$B$5*(1-'DCF_ADBE'!$B$6)+'DCF_ADBE'!$B$7-'DCF_ADBE'!$B$8)-'DCF_ADBE'!$B$3*(1+'DCF_ADBE'!$B$4)^1*'DCF_ADBE'!$B$4*'DCF_ADBE'!$B$9)/(1+0.10500000000000001)^2+('DCF_ADBE'!$B$3*(1+'DCF_ADBE'!$B$4)^3*('DCF_ADBE'!$B$5*(1-'DCF_ADBE'!$B$6)+'DCF_ADBE'!$B$7-'DCF_ADBE'!$B$8)-'DCF_ADBE'!$B$3*(1+'DCF_ADBE'!$B$4)^2*'DCF_ADBE'!$B$4*'DCF_ADBE'!$B$9)/(1+0.10500000000000001)^3+('DCF_ADBE'!$B$3*(1+'DCF_ADBE'!$B$4)^4*('DCF_ADBE'!$B$5*(1-'DCF_ADBE'!$B$6)+'DCF_ADBE'!$B$7-'DCF_ADBE'!$B$8)-'DCF_ADBE'!$B$3*(1+'DCF_ADBE'!$B$4)^3*'DCF_ADBE'!$B$4*'DCF_ADBE'!$B$9)/(1+0.10500000000000001)^4+('DCF_ADBE'!$B$3*(1+'DCF_ADBE'!$B$4)^5*('DCF_ADBE'!$B$5*(1-'DCF_ADBE'!$B$6)+'DCF_ADBE'!$B$7-'DCF_ADBE'!$B$8)-'DCF_ADBE'!$B$3*(1+'DCF_ADBE'!$B$4)^4*'DCF_ADBE'!$B$4*'DCF_ADBE'!$B$9)/(1+0.10500000000000001)^5+('DCF_ADBE'!$B$3*(1+'DCF_ADBE'!$B$4)^5*(1+0.035)*('DCF_ADBE'!$B$5*(1-'DCF_ADBE'!$B$6)+'DCF_ADBE'!$B$7-'DCF_ADBE'!$B$8)-'DCF_ADBE'!$B$3*(1+'DCF_ADBE'!$B$4)^5*0.035*'DCF_ADBE'!$B$9)/(0.10500000000000001-0.035)/(1+0.10500000000000001)^5-'DCF_ADBE'!$B$13)/'DCF_ADBE'!$B$12) -> 266.72196
A7: ADBE | B7: 0.11 | C7: =((('DCF_ADBE'!$B$3*(1+'DCF_ADBE'!$B$4)^1*('DCF_ADBE'!$B$5*(1-'DCF_ADBE'!$B$6)+'DCF_ADBE'!$B$7-'DCF_ADBE'!$B$8)-'DCF_ADBE'!$B$3*(1+'DCF_ADBE'!$B$4)^0*'DCF_ADBE'!$B$4*'DCF_ADBE'!$B$9)/(1+0.11)^1+('DCF_ADBE'!$B$3*(1+'DCF_ADBE'!$B$4)^2*('DCF_ADBE'!$B$5*(1-'DCF_ADBE'!$B$6)+'DCF_ADBE'!$B$7-'DCF_ADBE'!$B$8)-'DCF_ADBE'!$B$3*(1+'DCF_ADBE'!$B$4)^1*'DCF_ADBE'!$B$4*'DCF_ADBE'!$B$9)/(1+0.11)^2+('DCF_ADBE'!$B$3*(1+'DCF_ADBE'!$B$4)^3*('DCF_ADBE'!$B$5*(1-'DCF_ADBE'!$B$6)+'DCF_ADBE'!$B$7-'DCF_ADBE'!$B$8)-'DCF_ADBE'!$B$3*(1+'DCF_ADBE'!$B$4)^2*'DCF_ADBE'!$B$4*'DCF_ADBE'!$B$9)/(1+0.11)^3+('DCF_ADBE'!$B$3*(1+'DCF_ADBE'!$B$4)^4*('DCF_ADBE'!$B$5*(1-'DCF_ADBE'!$B$6)+'DCF_ADBE'!$B$7-'DCF_ADBE'!$B$8)-'DCF_ADBE'!$B$3*(1+'DCF_ADBE'!$B$4)^3*'DCF_ADBE'!$B$4*'DCF_ADBE'!$B$9)/(1+0.11)^4+('DCF_ADBE'!$B$3*(1+'DCF_ADBE'!$B$4)^5*('DCF_ADBE'!$B$5*(1-'DCF_ADBE'!$B$6)+'DCF_ADBE'!$B$7-'DCF_ADBE'!$B$8)-'DCF_ADBE'!$B$3*(1+'DCF_ADBE'!$B$4)^4*'DCF_ADBE'!$B$4*'DCF_ADBE'!$B$9)/(1+0.11)^5+('DCF_ADBE'!$B$3*(1+'DCF_ADBE'!$B$4)^5*(1+0.015000000000000001)*('DCF_ADBE'!$B$5*(1-'DCF_ADBE'!$B$6)+'DCF_ADBE'!$B$7-'DCF_ADBE'!$B$8)-'DCF_ADBE'!$B$3*(1+'DCF_ADBE'!$B$4)^5*0.015000000000000001*'DCF_ADBE'!$B$9)/(0.11-0.015000000000000001)/(1+0.11)^5-'DCF_ADBE'!$B$13)/'DCF_ADBE'!$B$12) -> 208.70014 | D7: =((('DCF_ADBE'!$B$3*(1+'DCF_ADBE'!$B$4)^1*('DCF_ADBE'!$B$5*(1-'DCF_ADBE'!$B$6)+'DCF_ADBE'!$B$7-'DCF_ADBE'!$B$8)-'DCF_ADBE'!$B$3*(1+'DCF_ADBE'!$B$4)^0*'DCF_ADBE'!$B$4*'DCF_ADBE'!$B$9)/(1+0.11)^1+('DCF_ADBE'!$B$3*(1+'DCF_ADBE'!$B$4)^2*('DCF_ADBE'!$B$5*(1-'DCF_ADBE'!$B$6)+'DCF_ADBE'!$B$7-'DCF_ADBE'!$B$8)-'DCF_ADBE'!$B$3*(1+'DCF_ADBE'!$B$4)^1*'DCF_ADBE'!$B$4*'DCF_ADBE'!$B$9)/(1+0.11)^2+('DCF_ADBE'!$B$3*(1+'DCF_ADBE'!$B$4)^3*('DCF_ADBE'!$B$5*(1-'DCF_ADBE'!$B$6)+'DCF_ADBE'!$B$7-'DCF_ADBE'!$B$8)-'DCF_ADBE'!$B$3*(1+'DCF_ADBE'!$B$4)^2*'DCF_ADBE'!$B$4*'DCF_ADBE'!$B$9)/(1+0.11)^3+('DCF_ADBE'!$B$3*(1+'DCF_ADBE'!$B$4)^4*('DCF_ADBE'!$B$5*(1-'DCF_ADBE'!$B$6)+'DCF_ADBE'!$B$7-'DCF_ADBE'!$B$8)-'DCF_ADBE'!$B$3*(1+'DCF_ADBE'!$B$4)^3*'DCF_ADBE'!$B$4*'DCF_ADBE'!$B$9)/(1+0.11)^4+('DCF_ADBE'!$B$3*(1+'DCF_ADBE'!$B$4)^5*('DCF_ADBE'!$B$5*(1-'DCF_ADBE'!$B$6)+'DCF_ADBE'!$B$7-'DCF_ADBE'!$B$8)-'DCF_ADBE'!$B$3*(1+'DCF_ADBE'!$B$4)^4*'DCF_ADBE'!$B$4*'DCF_ADBE'!$B$9)/(1+0.11)^5+('DCF_ADBE'!$B$3*(1+'DCF_ADBE'!$B$4)^5*(1+0.02)*('DCF_ADBE'!$B$5*(1-'DCF_ADBE'!$B$6)+'DCF_ADBE'!$B$7-'DCF_ADBE'!$B$8)-'DCF_ADBE'!$B$3*(1+'DCF_ADBE'!$B$4)^5*0.02*'DCF_ADBE'!$B$9)/(0.11-0.02)/(1+0.11)^5-'DCF_ADBE'!$B$13)/'DCF_ADBE'!$B$12) -> 217.03188 | E7: =((('DCF_ADBE'!$B$3*(1+'DCF_ADBE'!$B$4)^1*('DCF_ADBE'!$B$5*(1-'DCF_ADBE'!$B$6)+'DCF_ADBE'!$B$7-'DCF_ADBE'!$B$8)-'DCF_ADBE'!$B$3*(1+'DCF_ADBE'!$B$4)^0*'DCF_ADBE'!$B$4*'DCF_ADBE'!$B$9)/(1+0.11)^1+('DCF_ADBE'!$B$3*(1+'DCF_ADBE'!$B$4)^2*('DCF_ADBE'!$B$5*(1-'DCF_ADBE'!$B$6)+'DCF_ADBE'!$B$7-'DCF_ADBE'!$B$8)-'DCF_ADBE'!$B$3*(1+'DCF_ADBE'!$B$4)^1*'DCF_ADBE'!$B$4*'DCF_ADBE'!$B$9)/(1+0.11)^2+('DCF_ADBE'!$B$3*(1+'DCF_ADBE'!$B$4)^3*('DCF_ADBE'!$B$5*(1-'DCF_ADBE'!$B$6)+'DCF_ADBE'!$B$7-'DCF_ADBE'!$B$8)-'DCF_ADBE'!$B$3*(1+'DCF_ADBE'!$B$4)^2*'DCF_ADBE'!$B$4*'DCF_ADBE'!$B$9)/(1+0.11)^3+('DCF_ADBE'!$B$3*(1+'DCF_ADBE'!$B$4)^4*('DCF_ADBE'!$B$5*(1-'DCF_ADBE'!$B$6)+'DCF_ADBE'!$B$7-'DCF_ADBE'!$B$8)-'DCF_ADBE'!$B$3*(1+'DCF_ADBE'!$B$4)^3*'DCF_ADBE'!$B$4*'DCF_ADBE'!$B$9)/(1+0.11)^4+('DCF_ADBE'!$B$3*(1+'DCF_ADBE'!$B$4)^5*('DCF_ADBE'!$B$5*(1-'DCF_ADBE'!$B$6)+'DCF_ADBE'!$B$7-'DCF_ADBE'!$B$8)-'DCF_ADBE'!$B$3*(1+'DCF_ADBE'!$B$4)^4*'DCF_ADBE'!$B$4*'DCF_ADBE'!$B$9)/(1+0.11)^5+('DCF_ADBE'!$B$3*(1+'DCF_ADBE'!$B$4)^5*(1+0.025)*('DCF_ADBE'!$B$5*(1-'DCF_ADBE'!$B$6)+'DCF_ADBE'!$B$7-'DCF_ADBE'!$B$8)-'DCF_ADBE'!$B$3*(1+'DCF_ADBE'!$B$4)^5*0.025*'DCF_ADBE'!$B$9)/(0.11-0.025)/(1+0.11)^5-'DCF_ADBE'!$B$13)/'DCF_ADBE'!$B$12) -> 226.34384 | F7: =((('DCF_ADBE'!$B$3*(1+'DCF_ADBE'!$B$4)^1*('DCF_ADBE'!$B$5*(1-'DCF_ADBE'!$B$6)+'DCF_ADBE'!$B$7-'DCF_ADBE'!$B$8)-'DCF_ADBE'!$B$3*(1+'DCF_ADBE'!$B$4)^0*'DCF_ADBE'!$B$4*'DCF_ADBE'!$B$9)/(1+0.11)^1+('DCF_ADBE'!$B$3*(1+'DCF_ADBE'!$B$4)^2*('DCF_ADBE'!$B$5*(1-'DCF_ADBE'!$B$6)+'DCF_ADBE'!$B$7-'DCF_ADBE'!$B$8)-'DCF_ADBE'!$B$3*(1+'DCF_ADBE'!$B$4)^1*'DCF_ADBE'!$B$4*'DCF_ADBE'!$B$9)/(1+0.11)^2+('DCF_ADBE'!$B$3*(1+'DCF_ADBE'!$B$4)^3*('DCF_ADBE'!$B$5*(1-'DCF_ADBE'!$B$6)+'DCF_ADBE'!$B$7-'DCF_ADBE'!$B$8)-'DCF_ADBE'!$B$3*(1+'DCF_ADBE'!$B$4)^2*'DCF_ADBE'!$B$4*'DCF_ADBE'!$B$9)/(1+0.11)^3+('DCF_ADBE'!$B$3*(1+'DCF_ADBE'!$B$4)^4*('DCF_ADBE'!$B$5*(1-'DCF_ADBE'!$B$6)+'DCF_ADBE'!$B$7-'DCF_ADBE'!$B$8)-'DCF_ADBE'!$B$3*(1+'DCF_ADBE'!$B$4)^3*'DCF_ADBE'!$B$4*'DCF_ADBE'!$B$9)/(1+0.11)^4+('DCF_ADBE'!$B$3*(1+'DCF_ADBE'!$B$4)^5*('DCF_ADBE'!$B$5*(1-'DCF_ADBE'!$B$6)+'DCF_ADBE'!$B$7-'DCF_ADBE'!$B$8)-'DCF_ADBE'!$B$3*(1+'DCF_ADBE'!$B$4)^4*'DCF_ADBE'!$B$4*'DCF_ADBE'!$B$9)/(1+0.11)^5+('DCF_ADBE'!$B$3*(1+'DCF_ADBE'!$B$4)^5*(1+0.030000000000000002)*('DCF_ADBE'!$B$5*(1-'DCF_ADBE'!$B$6)+'DCF_ADBE'!$B$7-'DCF_ADBE'!$B$8)-'DCF_ADBE'!$B$3*(1+'DCF_ADBE'!$B$4)^5*0.030000000000000002*'DCF_ADBE'!$B$9)/(0.11-0.030000000000000002)/(1+0.11)^5-'DCF_ADBE'!$B$13)/'DCF_ADBE'!$B$12) -> 236.81978 | G7: =((('DCF_ADBE'!$B$3*(1+'DCF_ADBE'!$B$4)^1*('DCF_ADBE'!$B$5*(1-'DCF_ADBE'!$B$6)+'DCF_ADBE'!$B$7-'DCF_ADBE'!$B$8)-'DCF_ADBE'!$B$3*(1+'DCF_ADBE'!$B$4)^0*'DCF_ADBE'!$B$4*'DCF_ADBE'!$B$9)/(1+0.11)^1+('DCF_ADBE'!$B$3*(1+'DCF_ADBE'!$B$4)^2*('DCF_ADBE'!$B$5*(1-'DCF_ADBE'!$B$6)+'DCF_ADBE'!$B$7-'DCF_ADBE'!$B$8)-'DCF_ADBE'!$B$3*(1+'DCF_ADBE'!$B$4)^1*'DCF_ADBE'!$B$4*'DCF_ADBE'!$B$9)/(1+0.11)^2+('DCF_ADBE'!$B$3*(1+'DCF_ADBE'!$B$4)^3*('DCF_ADBE'!$B$5*(1-'DCF_ADBE'!$B$6)+'DCF_ADBE'!$B$7-'DCF_ADBE'!$B$8)-'DCF_ADBE'!$B$3*(1+'DCF_ADBE'!$B$4)^2*'DCF_ADBE'!$B$4*'DCF_ADBE'!$B$9)/(1+0.11)^3+('DCF_ADBE'!$B$3*(1+'DCF_ADBE'!$B$4)^4*('DCF_ADBE'!$B$5*(1-'DCF_ADBE'!$B$6)+'DCF_ADBE'!$B$7-'DCF_ADBE'!$B$8)-'DCF_ADBE'!$B$3*(1+'DCF_ADBE'!$B$4)^3*'DCF_ADBE'!$B$4*'DCF_ADBE'!$B$9)/(1+0.11)^4+('DCF_ADBE'!$B$3*(1+'DCF_ADBE'!$B$4)^5*('DCF_ADBE'!$B$5*(1-'DCF_ADBE'!$B$6)+'DCF_ADBE'!$B$7-'DCF_ADBE'!$B$8)-'DCF_ADBE'!$B$3*(1+'DCF_ADBE'!$B$4)^4*'DCF_ADBE'!$B$4*'DCF_ADBE'!$B$9)/(1+0.11)^5+('DCF_ADBE'!$B$3*(1+'DCF_ADBE'!$B$4)^5*(1+0.035)*('DCF_ADBE'!$B$5*(1-'DCF_ADBE'!$B$6)+'DCF_ADBE'!$B$7-'DCF_ADBE'!$B$8)-'DCF_ADBE'!$B$3*(1+'DCF_ADBE'!$B$4)^5*0.035*'DCF_ADBE'!$B$9)/(0.11-0.035)/(1+0.11)^5-'DCF_ADBE'!$B$13)/'DCF_ADBE'!$B$12) -> 248.69252
